Workbook

Sheet Full Stock List
A1: Barcode | B1: Sub Category | C1: Category | D1: Product Name | E1: Carton Size | F1: Grand Total | G1: Juice Fridge | H1: Upper Keg | I1: Astral Bar | J1: GB1 Bar | K1: GB2 Bar | L1: CB1 Bar | M1: CB2 Bar | N1: CB3 Bar | O1: Spirits Room | P1: White Wine Fridge | Q1: Lower Keg | R1: Botanical Storeroom | S1: Botanical Bar | T1: Loading Dock Fridge | U1: Postmix Loading Dock | V1: Postmix Lower Keg | W1: Postmix TWR
A2: 66549 | B2: BEER AUS PACK | C2: BEER | D2: BROOKVALE GINGER BEER 330ML STUBBIE CTNx24EA | E2: 24 | F2: =G2+H2+I2+J2+K2+L2+M2+N2+O2+P2+Q2+R2+S2+T2+U2+V2+W2 -> 0 | G2: =IFERROR(INDEX('Juice Fridge'!$F$2:$F$300,MATCH(A2,'Juice Fridge'!$A$2:$A$300,0)),0) -> 0 | H2: =IFERROR(INDEX('Upper Keg'!$F$2:$F$300,MATCH(A2,'Upper Keg'!$A$2:$A$300,0)),0) -> 0 | I2: =IFERROR(INDEX('Astral Bar'!$F$2:$F$300,MATCH(A2,'Astral Bar'!$A$2:$A$300,0)),0) -> 0 | J2: =IFERROR(INDEX('GB1 Bar'!$F$2:$F$300,MATCH(A2,'GB1 Bar'!$A$2:$A$300,0)),0) -> 0 | K2: =IFERROR(INDEX('GB2 Bar'!$F$2:$F$300,MATCH(A2,'GB2 Bar'!$A$2:$A$300,0)),0) -> 0 | L2: =IFERROR(INDEX('CB1 Bar'!$F$2:$F$300,MATCH(A2,'CB1 Bar'!$A$2:$A$300,0)),0) -> 0 | M2: =IFERROR(INDEX('CB2 Bar'!$F$2:$F$300,MATCH(A2,'CB2 Bar'!$A$2:$A$300,0)),0) -> 0 | N2: =IFERROR(INDEX('CB3 Bar'!$F$2:$F$300,MATCH(A2,'CB3 Bar'!$A$2:$A$300,0)),0) -> 0 | O2: =IFERROR(INDEX('Spirits Room'!$F$2:$F$300,MATCH(A2,'Spirits Room'!$A$2:$A$300,0)),0) -> 0 | P2: =IFERROR(INDEX('White Wine Fridge'!$F$2:$F$300,MATCH(A2,'White Wine Fridge'!$A$2:$A$300,0)),0) -> 0 | Q2: =IFERROR(INDEX('Lower Keg'!$F$2:$F$300,MATCH(A2,'Lower Keg'!$A$2:$A$300,0)),0) -> 0 | R2: =IFERROR(INDEX('Botanical Storeroom'!$F$2:$F$300,MATCH(A2,'Botanical Storeroom'!$A$2:$A$300,0)),0) -> 0 | S2: =IFERROR(INDEX('Botanical Bar'!$F$2:$F$300,MATCH(A2,'Botanical Bar'!$A$2:$A$300,0)),0) -> 0 | T2: =IFERROR(INDEX('Loading Dock Fridge'!$F$2:$F$300,MATCH(A2,'Loading Dock Fridge'!$A$2:$A$300,0)),0) -> 0 | U2: =IFERROR(INDEX('Postmix Loading Dock'!$F$2:$F$300,MATCH(A2,'Postmix Loading Dock'!$A$2:$A$300,0)),0) -> 0 | V2: =IFERROR(INDEX('Postmix Lower Keg'!$F$2:$F$300,MATCH(A2,'Postmix Lower Keg'!$A$2:$A$300,0)),0) -> 0 | W2: =IFERROR(INDEX('Postmix TWR'!$F$2:$F$300,MATCH(A2,'Postmix TWR'!$A$2:$A$300,0)),0) -> 0
A3: 59237 | B3: BEER AUS PACK | C3: BEER | D3: CARLTON DRY STUBBIE 330ML CTNX24EA | E3: 24 | F3: =G3+H3+I3+J3+K3+L3+M3+N3+O3+P3+Q3+R3+S3+T3+U3+V3+W3 -> 0 | G3: =IFERROR(INDEX('Juice Fridge'!$F$2:$F$300,MATCH(A3,'Juice Fridge'!$A$2:$A$300,0)),0) -> 0 | H3: =IFERROR(INDEX('Upper Keg'!$F$2:$F$300,MATCH(A3,'Upper Keg'!$A$2:$A$300,0)),0) -> 0 | I3: =IFERROR(INDEX('Astral Bar'!$F$2:$F$300,MATCH(A3,'Astral Bar'!$A$2:$A$300,0)),0) -> 0 | J3: =IFERROR(INDEX('GB1 Bar'!$F$2:$F$300,MATCH(A3,'GB1 Bar'!$A$2:$A$300,0)),0) -> 0 | K3: =IFERROR(INDEX('GB2 Bar'!$F$2:$F$300,MATCH(A3,'GB2 Bar'!$A$2:$A$300,0)),0) -> 0 | L3: =IFERROR(INDEX('CB1 Bar'!$F$2:$F$300,MATCH(A3,'CB1 Bar'!$A$2:$A$300,0)),0) -> 0 | M3: =IFERROR(INDEX('CB2 Bar'!$F$2:$F$300,MATCH(A3,'CB2 Bar'!$A$2:$A$300,0)),0) -> 0 | N3: =IFERROR(INDEX('CB3 Bar'!$F$2:$F$300,MATCH(A3,'CB3 Bar'!$A$2:$A$300,0)),0) -> 0 | O3: =IFERROR(INDEX('Spirits Room'!$F$2:$F$300,MATCH(A3,'Spirits Room'!$A$2:$A$300,0)),0) -> 0 | P3: =IFERROR(INDEX('White Wine Fridge'!$F$2:$F$300,MATCH(A3,'White Wine Fridge'!$A$2:$A$300,0)),0) -> 0 | Q3: =IFERROR(INDEX('Lower Keg'!$F$2:$F$300,MATCH(A3,'Lower Keg'!$A$2:$A$300,0)),0) -> 0 | R3: =IFERROR(INDEX('Botanical Storeroom'!$F$2:$F$300,MATCH(A3,'Botanical Storeroom'!$A$2:$A$300,0)),0) -> 0 | S3: =IFERROR(INDEX('Botanical Bar'!$F$2:$F$300,MATCH(A3,'Botanical Bar'!$A$2:$A$300,0)),0) -> 0 | T3: =IFERROR(INDEX('Loading Dock Fridge'!$F$2:$F$300,MATCH(A3,'Loading Dock Fridge'!$A$2:$A$300,0)),0) -> 0 | U3: =IFERROR(INDEX('Postmix Loading Dock'!$F$2:$F$300,MATCH(A3,'Postmix Loading Dock'!$A$2:$A$300,0)),0) -> 0 | V3: =IFERROR(INDEX('Postmix Lower Keg'!$F$2:$F$300,MATCH(A3,'Postmix Lower Keg'!$A$2:$A$300,0)),0) -> 0 | W3: =IFERROR(INDEX('Postmix TWR'!$F$2:$F$300,MATCH(A3,'Postmix TWR'!$A$2:$A$300,0)),0) -> 0
A4: 64212 | B4: BEER AUS PACK | C4: BEER | D4: CARLTON ZERO STUBBIE 330ML CTNx24EA | E4: 24 | F4: =G4+H4+I4+J4+K4+L4+M4+N4+O4+P4+Q4+R4+S4+T4+U4+V4+W4 -> 0 | G4: =IFERROR(INDEX('Juice Fridge'!$F$2:$F$300,MATCH(A4,'Juice Fridge'!$A$2:$A$300,0)),0) -> 0 | H4: =IFERROR(INDEX('Upper Keg'!$F$2:$F$300,MATCH(A4,'Upper Keg'!$A$2:$A$300,0)),0) -> 0 | I4: =IFERROR(INDEX('Astral Bar'!$F$2:$F$300,MATCH(A4,'Astral Bar'!$A$2:$A$300,0)),0) -> 0 | J4: =IFERROR(INDEX('GB1 Bar'!$F$2:$F$300,MATCH(A4,'GB1 Bar'!$A$2:$A$300,0)),0) -> 0 | K4: =IFERROR(INDEX('GB2 Bar'!$F$2:$F$300,MATCH(A4,'GB2 Bar'!$A$2:$A$300,0)),0) -> 0 | L4: =IFERROR(INDEX('CB1 Bar'!$F$2:$F$300,MATCH(A4,'CB1 Bar'!$A$2:$A$300,0)),0) -> 0 | M4: =IFERROR(INDEX('CB2 Bar'!$F$2:$F$300,MATCH(A4,'CB2 Bar'!$A$2:$A$300,0)),0) -> 0 | N4: =IFERROR(INDEX('CB3 Bar'!$F$2:$F$300,MATCH(A4,'CB3 Bar'!$A$2:$A$300,0)),0) -> 0 | O4: =IFERROR(INDEX('Spirits Room'!$F$2:$F$300,MATCH(A4,'Spirits Room'!$A$2:$A$300,0)),0) -> 0 | P4: =IFERROR(INDEX('White Wine Fridge'!$F$2:$F$300,MATCH(A4,'White Wine Fridge'!$A$2:$A$300,0)),0) -> 0 | Q4: =IFERROR(INDEX('Lower Keg'!$F$2:$F$300,MATCH(A4,'Lower Keg'!$A$2:$A$300,0)),0) -> 0 | R4: =IFERROR(INDEX('Botanical Storeroom'!$F$2:$F$300,MATCH(A4,'Botanical Storeroom'!$A$2:$A$300,0)),0) -> 0 | S4: =IFERROR(INDEX('Botanical Bar'!$F$2:$F$300,MATCH(A4,'Botanical Bar'!$A$2:$A$300,0)),0) -> 0 | T4: =IFERROR(INDEX('Loading Dock Fridge'!$F$2:$F$300,MATCH(A4,'Loading Dock Fridge'!$A$2:$A$300,0)),0) -> 0 | U4: =IFERROR(INDEX('Postmix Loading Dock'!$F$2:$F$300,MATCH(A4,'Postmix Loading Dock'!$A$2:$A$300,0)),0) -> 0 | V4: =IFERROR(INDEX('Postmix Lower Keg'!$F$2:$F$300,MATCH(A4,'Postmix Lower Keg'!$A$2:$A$300,0)),0) -> 0 | W4: =IFERROR(INDEX('Postmix TWR'!$F$2:$F$300,MATCH(A4,'Postmix TWR'!$A$2:$A$300,0)),0) -> 0
A5: 54419 | B5: BEER AUS PACK | C5: BEER | D5: GREAT NORTHERN SUPER CRISP LAGER 330ML CTNx24EA | E5: 24 | F5: =G5+H5+I5+J5+K5+L5+M5+N5+O5+P5+Q5+R5+S5+T5+U5+V5+W5 -> 0 | G5: =IFERROR(INDEX('Juice Fridge'!$F$2:$F$300,MATCH(A5,'Juice Fridge'!$A$2:$A$300,0)),0) -> 0 | H5: =IFERROR(INDEX('Upper Keg'!$F$2:$F$300,MATCH(A5,'Upper Keg'!$A$2:$A$300,0)),0) -> 0 | I5: =IFERROR(INDEX('Astral Bar'!$F$2:$F$300,MATCH(A5,'Astral Bar'!$A$2:$A$300,0)),0) -> 0 | J5: =IFERROR(INDEX('GB1 Bar'!$F$2:$F$300,MATCH(A5,'GB1 Bar'!$A$2:$A$300,0)),0) -> 0 | K5: =IFERROR(INDEX('GB2 Bar'!$F$2:$F$300,MATCH(A5,'GB2 Bar'!$A$2:$A$300,0)),0) -> 0 | L5: =IFERROR(INDEX('CB1 Bar'!$F$2:$F$300,MATCH(A5,'CB1 Bar'!$A$2:$A$300,0)),0) -> 0 | M5: =IFERROR(INDEX('CB2 Bar'!$F$2:$F$300,MATCH(A5,'CB2 Bar'!$A$2:$A$300,0)),0) -> 0 | N5: =IFERROR(INDEX('CB3 Bar'!$F$2:$F$300,MATCH(A5,'CB3 Bar'!$A$2:$A$300,0)),0) -> 0 | O5: =IFERROR(INDEX('Spirits Room'!$F$2:$F$300,MATCH(A5,'Spirits Room'!$A$2:$A$300,0)),0) -> 0 | P5: =IFERROR(INDEX('White Wine Fridge'!$F$2:$F$300,MATCH(A5,'White Wine Fridge'!$A$2:$A$300,0)),0) -> 0 | Q5: =IFERROR(INDEX('Lower Keg'!$F$2:$F$300,MATCH(A5,'Lower Keg'!$A$2:$A$300,0)),0) -> 0 | R5: =IFERROR(INDEX('Botanical Storeroom'!$F$2:$F$300,MATCH(A5,'Botanical Storeroom'!$A$2:$A$300,0)),0) -> 0 | S5: =IFERROR(INDEX('Botanical Bar'!$F$2:$F$300,MATCH(A5,'Botanical Bar'!$A$2:$A$300,0)),0) -> 0 | T5: =IFERROR(INDEX('Loading Dock Fridge'!$F$2:$F$300,MATCH(A5,'Loading Dock Fridge'!$A$2:$A$300,0)),0) -> 0 | U5: =IFERROR(INDEX('Postmix Loading Dock'!$F$2:$F$300,MATCH(A5,'Postmix Loading Dock'!$A$2:$A$300,0)),0) -> 0 | V5: =IFERROR(INDEX('Postmix Lower Keg'!$F$2:$F$300,MATCH(A5,'Postmix Lower Keg'!$A$2:$A$300,0)),0) -> 0 | W5: =IFERROR(INDEX('Postmix TWR'!$F$2:$F$300,MATCH(A5,'Postmix TWR'!$A$2:$A$300,0)),0) -> 0
A6: 60039 | B6: BEER AUS PACK | C6: BEER | D6: HAHN ULTRA CRISP GLUTEN FREE 4.2% 330ML CTNx24EA | E6: 24 | F6: =G6+H6+I6+J6+K6+L6+M6+N6+O6+P6+Q6+R6+S6+T6+U6+V6+W6 -> 0 | G6: =IFERROR(INDEX('Juice Fridge'!$F$2:$F$300,MATCH(A6,'Juice Fridge'!$A$2:$A$300,0)),0) -> 0 | H6: =IFERROR(INDEX('Upper Keg'!$F$2:$F$300,MATCH(A6,'Upper Keg'!$A$2:$A$300,0)),0) -> 0 | I6: =IFERROR(INDEX('Astral Bar'!$F$2:$F$300,MATCH(A6,'Astral Bar'!$A$2:$A$300,0)),0) -> 0 | J6: =IFERROR(INDEX('GB1 Bar'!$F$2:$F$300,MATCH(A6,'GB1 Bar'!$A$2:$A$300,0)),0) -> 0 | K6: =IFERROR(INDEX('GB2 Bar'!$F$2:$F$300,MATCH(A6,'GB2 Bar'!$A$2:$A$300,0)),0) -> 0 | L6: =IFERROR(INDEX('CB1 Bar'!$F$2:$F$300,MATCH(A6,'CB1 Bar'!$A$2:$A$300,0)),0) -> 0 | M6: =IFERROR(INDEX('CB2 Bar'!$F$2:$F$300,MATCH(A6,'CB2 Bar'!$A$2:$A$300,0)),0) -> 0 | N6: =IFERROR(INDEX('CB3 Bar'!$F$2:$F$300,MATCH(A6,'CB3 Bar'!$A$2:$A$300,0)),0) -> 0 | O6: =IFERROR(INDEX('Spirits Room'!$F$2:$F$300,MATCH(A6,'Spirits Room'!$A$2:$A$300,0)),0) -> 0 | P6: =IFERROR(INDEX('White Wine Fridge'!$F$2:$F$300,MATCH(A6,'White Wine Fridge'!$A$2:$A$300,0)),0) -> 0 | Q6: =IFERROR(INDEX('Lower Keg'!$F$2:$F$300,MATCH(A6,'Lower Keg'!$A$2:$A$300,0)),0) -> 0 | R6: =IFERROR(INDEX('Botanical Storeroom'!$F$2:$F$300,MATCH(A6,'Botanical Storeroom'!$A$2:$A$300,0)),0) -> 0 | S6: =IFERROR(INDEX('Botanical Bar'!$F$2:$F$300,MATCH(A6,'Botanical Bar'!$A$2:$A$300,0)),0) -> 0 | T6: =IFERROR(INDEX('Loading Dock Fridge'!$F$2:$F$300,MATCH(A6,'Loading Dock Fridge'!$A$2:$A$300,0)),0) -> 0 | U6: =IFERROR(INDEX('Postmix Loading Dock'!$F$2:$F$300,MATCH(A6,'Postmix Loading Dock'!$A$2:$A$300,0)),0) -> 0 | V6: =IFERROR(INDEX('Postmix Lower Keg'!$F$2:$F$300,MATCH(A6,'Postmix Lower Keg'!$A$2:$A$300,0)),0) -> 0 | W6: =IFERROR(INDEX('Postmix TWR'!$F$2:$F$300,MATCH(A6,'Postmix TWR'!$A$2:$A$300,0)),0) -> 0
A7: 69689 | B7: BEER AUS PACK | C7: BEER | D7: SWAN DRAUGHT 375ML CAN CTN X24 | E7: 24 | F7: =G7+H7+I7+J7+K7+L7+M7+N7+O7+P7+Q7+R7+S7+T7+U7+V7+W7 -> 0 | G7: =IFERROR(INDEX('Juice Fridge'!$F$2:$F$300,MATCH(A7,'Juice Fridge'!$A$2:$A$300,0)),0) -> 0 | H7: =IFERROR(INDEX('Upper Keg'!$F$2:$F$300,MATCH(A7,'Upper Keg'!$A$2:$A$300,0)),0) -> 0 | I7: =IFERROR(INDEX('Astral Bar'!$F$2:$F$300,MATCH(A7,'Astral Bar'!$A$2:$A$300,0)),0) -> 0 | J7: =IFERROR(INDEX('GB1 Bar'!$F$2:$F$300,MATCH(A7,'GB1 Bar'!$A$2:$A$300,0)),0) -> 0 | K7: =IFERROR(INDEX('GB2 Bar'!$F$2:$F$300,MATCH(A7,'GB2 Bar'!$A$2:$A$300,0)),0) -> 0 | L7: =IFERROR(INDEX('CB1 Bar'!$F$2:$F$300,MATCH(A7,'CB1 Bar'!$A$2:$A$300,0)),0) -> 0 | M7: =IFERROR(INDEX('CB2 Bar'!$F$2:$F$300,MATCH(A7,'CB2 Bar'!$A$2:$A$300,0)),0) -> 0 | N7: =IFERROR(INDEX('CB3 Bar'!$F$2:$F$300,MATCH(A7,'CB3 Bar'!$A$2:$A$300,0)),0) -> 0 | O7: =IFERROR(INDEX('Spirits Room'!$F$2:$F$300,MATCH(A7,'Spirits Room'!$A$2:$A$300,0)),0) -> 0 | P7: =IFERROR(INDEX('White Wine Fridge'!$F$2:$F$300,MATCH(A7,'White Wine Fridge'!$A$2:$A$300,0)),0) -> 0 | Q7: =IFERROR(INDEX('Lower Keg'!$F$2:$F$300,MATCH(A7,'Lower Keg'!$A$2:$A$300,0)),0) -> 0 | R7: =IFERROR(INDEX('Botanical Storeroom'!$F$2:$F$300,MATCH(A7,'Botanical Storeroom'!$A$2:$A$300,0)),0) -> 0 | S7: =IFERROR(INDEX('Botanical Bar'!$F$2:$F$300,MATCH(A7,'Botanical Bar'!$A$2:$A$300,0)),0) -> 0 | T7: =IFERROR(INDEX('Loading Dock Fridge'!$F$2:$F$300,MATCH(A7,'Loading Dock Fridge'!$A$2:$A$300,0)),0) -> 0 | U7: =IFERROR(INDEX('Postmix Loading Dock'!$F$2:$F$300,MATCH(A7,'Postmix Loading Dock'!$A$2:$A$300,0)),0) -> 0 | V7: =IFERROR(INDEX('Postmix Lower Keg'!$F$2:$F$300,MATCH(A7,'Postmix Lower Keg'!$A$2:$A$300,0)),0) -> 0 | W7: =IFERROR(INDEX('Postmix TWR'!$F$2:$F$300,MATCH(A7,'Postmix TWR'!$A$2:$A$300,0)),0) -> 0
A8: 60612 | B8: BEER IMP PACK | C8: BEER | D8: HEINEKEN ZERO 0.0% STUBBIE 330ML CTNx24EA | E8: 24 | F8: =G8+H8+I8+J8+K8+L8+M8+N8+O8+P8+Q8+R8+S8+T8+U8+V8+W8 -> 0 | G8: =IFERROR(INDEX('Juice Fridge'!$F$2:$F$300,MATCH(A8,'Juice Fridge'!$A$2:$A$300,0)),0) -> 0 | H8: =IFERROR(INDEX('Upper Keg'!$F$2:$F$300,MATCH(A8,'Upper Keg'!$A$2:$A$300,0)),0) -> 0 | I8: =IFERROR(INDEX('Astral Bar'!$F$2:$F$300,MATCH(A8,'Astral Bar'!$A$2:$A$300,0)),0) -> 0 | J8: =IFERROR(INDEX('GB1 Bar'!$F$2:$F$300,MATCH(A8,'GB1 Bar'!$A$2:$A$300,0)),0) -> 0 | K8: =IFERROR(INDEX('GB2 Bar'!$F$2:$F$300,MATCH(A8,'GB2 Bar'!$A$2:$A$300,0)),0) -> 0 | L8: =IFERROR(INDEX('CB1 Bar'!$F$2:$F$300,MATCH(A8,'CB1 Bar'!$A$2:$A$300,0)),0) -> 0 | M8: =IFERROR(INDEX('CB2 Bar'!$F$2:$F$300,MATCH(A8,'CB2 Bar'!$A$2:$A$300,0)),0) -> 0 | N8: =IFERROR(INDEX('CB3 Bar'!$F$2:$F$300,MATCH(A8,'CB3 Bar'!$A$2:$A$300,0)),0) -> 0 | O8: =IFERROR(INDEX('Spirits Room'!$F$2:$F$300,MATCH(A8,'Spirits Room'!$A$2:$A$300,0)),0) -> 0 | P8: =IFERROR(INDEX('White Wine Fridge'!$F$2:$F$300,MATCH(A8,'White Wine Fridge'!$A$2:$A$300,0)),0) -> 0 | Q8: =IFERROR(INDEX('Lower Keg'!$F$2:$F$300,MATCH(A8,'Lower Keg'!$A$2:$A$300,0)),0) -> 0 | R8: =IFERROR(INDEX('Botanical Storeroom'!$F$2:$F$300,MATCH(A8,'Botanical Storeroom'!$A$2:$A$300,0)),0) -> 0 | S8: =IFERROR(INDEX('Botanical Bar'!$F$2:$F$300,MATCH(A8,'Botanical Bar'!$A$2:$A$300,0)),0) -> 0 | T8: =IFERROR(INDEX('Loading Dock Fridge'!$F$2:$F$300,MATCH(A8,'Loading Dock Fridge'!$A$2:$A$300,0)),0) -> 0 | U8: =IFERROR(INDEX('Postmix Loading Dock'!$F$2:$F$300,MATCH(A8,'Postmix Loading Dock'!$A$2:$A$300,0)),0) -> 0 | V8: =IFERROR(INDEX('Postmix Lower Keg'!$F$2:$F$300,MATCH(A8,'Postmix Lower Keg'!$A$2:$A$300,0)),0) -> 0 | W8: =IFERROR(INDEX('Postmix TWR'!$F$2:$F$300,MATCH(A8,'Postmix TWR'!$A$2:$A$300,0)),0) -> 0
A9: 116393 | B9: BEER PACK | C9: BEER | D9: HAHN LIGHT PREMIUM STUBBIE 375ML 3547 CTNx24EA | E9: 24 | F9: =G9+H9+I9+J9+K9+L9+M9+N9+O9+P9+Q9+R9+S9+T9+U9+V9+W9 -> 0 | G9: =IFERROR(INDEX('Juice Fridge'!$F$2:$F$300,MATCH(A9,'Juice Fridge'!$A$2:$A$300,0)),0) -> 0 | H9: =IFERROR(INDEX('Upper Keg'!$F$2:$F$300,MATCH(A9,'Upper Keg'!$A$2:$A$300,0)),0) -> 0 | I9: =IFERROR(INDEX('Astral Bar'!$F$2:$F$300,MATCH(A9,'Astral Bar'!$A$2:$A$300,0)),0) -> 0 | J9: =IFERROR(INDEX('GB1 Bar'!$F$2:$F$300,MATCH(A9,'GB1 Bar'!$A$2:$A$300,0)),0) -> 0 | K9: =IFERROR(INDEX('GB2 Bar'!$F$2:$F$300,MATCH(A9,'GB2 Bar'!$A$2:$A$300,0)),0) -> 0 | L9: =IFERROR(INDEX('CB1 Bar'!$F$2:$F$300,MATCH(A9,'CB1 Bar'!$A$2:$A$300,0)),0) -> 0 | M9: =IFERROR(INDEX('CB2 Bar'!$F$2:$F$300,MATCH(A9,'CB2 Bar'!$A$2:$A$300,0)),0) -> 0 | N9: =IFERROR(INDEX('CB3 Bar'!$F$2:$F$300,MATCH(A9,'CB3 Bar'!$A$2:$A$300,0)),0) -> 0 | O9: =IFERROR(INDEX('Spirits Room'!$F$2:$F$300,MATCH(A9,'Spirits Room'!$A$2:$A$300,0)),0) -> 0 | P9: =IFERROR(INDEX('White Wine Fridge'!$F$2:$F$300,MATCH(A9,'White Wine Fridge'!$A$2:$A$300,0)),0) -> 0 | Q9: =IFERROR(INDEX('Lower Keg'!$F$2:$F$300,MATCH(A9,'Lower Keg'!$A$2:$A$300,0)),0) -> 0 | R9: =IFERROR(INDEX('Botanical Storeroom'!$F$2:$F$300,MATCH(A9,'Botanical Storeroom'!$A$2:$A$300,0)),0) -> 0 | S9: =IFERROR(INDEX('Botanical Bar'!$F$2:$F$300,MATCH(A9,'Botanical Bar'!$A$2:$A$300,0)),0) -> 0 | T9: =IFERROR(INDEX('Loading Dock Fridge'!$F$2:$F$300,MATCH(A9,'Loading Dock Fridge'!$A$2:$A$300,0)),0) -> 0 | U9: =IFERROR(INDEX('Postmix Loading Dock'!$F$2:$F$300,MATCH(A9,'Postmix Loading Dock'!$A$2:$A$300,0)),0) -> 0 | V9: =IFERROR(INDEX('Postmix Lower Keg'!$F$2:$F$300,MATCH(A9,'Postmix Lower Keg'!$A$2:$A$300,0)),0) -> 0 | W9: =IFERROR(INDEX('Postmix TWR'!$F$2:$F$300,MATCH(A9,'Postmix TWR'!$A$2:$A$300,0)),0) -> 0
A10: 383 | B10: BEER PACK | C10: BEER | D10: CORONA BEER 355ML CTNx24EA | E10: 24 | F10: =G10+H10+I10+J10+K10+L10+M10+N10+O10+P10+Q10+R10+S10+T10+U10+V10+W10 -> 0 | G10: =IFERROR(INDEX('Juice Fridge'!$F$2:$F$300,MATCH(A10,'Juice Fridge'!$A$2:$A$300,0)),0) -> 0 | H10: =IFERROR(INDEX('Upper Keg'!$F$2:$F$300,MATCH(A10,'Upper Keg'!$A$2:$A$300,0)),0) -> 0 | I10: =IFERROR(INDEX('Astral Bar'!$F$2:$F$300,MATCH(A10,'Astral Bar'!$A$2:$A$300,0)),0) -> 0 | J10: =IFERROR(INDEX('GB1 Bar'!$F$2:$F$300,MATCH(A10,'GB1 Bar'!$A$2:$A$300,0)),0) -> 0 | K10: =IFERROR(INDEX('GB2 Bar'!$F$2:$F$300,MATCH(A10,'GB2 Bar'!$A$2:$A$300,0)),0) -> 0 | L10: =IFERROR(INDEX('CB1 Bar'!$F$2:$F$300,MATCH(A10,'CB1 Bar'!$A$2:$A$300,0)),0) -> 0 | M10: =IFERROR(INDEX('CB2 Bar'!$F$2:$F$300,MATCH(A10,'CB2 Bar'!$A$2:$A$300,0)),0) -> 0 | N10: =IFERROR(INDEX('CB3 Bar'!$F$2:$F$300,MATCH(A10,'CB3 Bar'!$A$2:$A$300,0)),0) -> 0 | O10: =IFERROR(INDEX('Spirits Room'!$F$2:$F$300,MATCH(A10,'Spirits Room'!$A$2:$A$300,0)),0) -> 0 | P10: =IFERROR(INDEX('White Wine Fridge'!$F$2:$F$300,MATCH(A10,'White Wine Fridge'!$A$2:$A$300,0)),0) -> 0 | Q10: =IFERROR(INDEX('Lower Keg'!$F$2:$F$300,MATCH(A10,'Lower Keg'!$A$2:$A$300,0)),0) -> 0 | R10: =IFERROR(INDEX('Botanical Storeroom'!$F$2:$F$300,MATCH(A10,'Botanical Storeroom'!$A$2:$A$300,0)),0) -> 0 | S10: =IFERROR(INDEX('Botanical Bar'!$F$2:$F$300,MATCH(A10,'Botanical Bar'!$A$2:$A$300,0)),0) -> 0 | T10: =IFERROR(INDEX('Loading Dock Fridge'!$F$2:$F$300,MATCH(A10,'Loading Dock Fridge'!$A$2:$A$300,0)),0) -> 0 | U10: =IFERROR(INDEX('Postmix Loading Dock'!$F$2:$F$300,MATCH(A10,'Postmix Loading Dock'!$A$2:$A$300,0)),0) -> 0 | V10: =IFERROR(INDEX('Postmix Lower Keg'!$F$2:$F$300,MATCH(A10,'Postmix Lower Keg'!$A$2:$A$300,0)),0) -> 0 | W10: =IFERROR(INDEX('Postmix TWR'!$F$2:$F$300,MATCH(A10,'Postmix TWR'!$A$2:$A$300,0)),0) -> 0
A11: 191 | B11: BEER PACK | C11: BEER | D11: CROWN LAGER STUBBIE 24X375ML | E11: 24 | F11: =G11+H11+I11+J11+K11+L11+M11+N11+O11+P11+Q11+R11+S11+T11+U11+V11+W11 -> 0 | G11: =IFERROR(INDEX('Juice Fridge'!$F$2:$F$300,MATCH(A11,'Juice Fridge'!$A$2:$A$300,0)),0) -> 0 | H11: =IFERROR(INDEX('Upper Keg'!$F$2:$F$300,MATCH(A11,'Upper Keg'!$A$2:$A$300,0)),0) -> 0 | I11: =IFERROR(INDEX('Astral Bar'!$F$2:$F$300,MATCH(A11,'Astral Bar'!$A$2:$A$300,0)),0) -> 0 | J11: =IFERROR(INDEX('GB1 Bar'!$F$2:$F$300,MATCH(A11,'GB1 Bar'!$A$2:$A$300,0)),0) -> 0 | K11: =IFERROR(INDEX('GB2 Bar'!$F$2:$F$300,MATCH(A11,'GB2 Bar'!$A$2:$A$300,0)),0) -> 0 | L11: =IFERROR(INDEX('CB1 Bar'!$F$2:$F$300,MATCH(A11,'CB1 Bar'!$A$2:$A$300,0)),0) -> 0 | M11: =IFERROR(INDEX('CB2 Bar'!$F$2:$F$300,MATCH(A11,'CB2 Bar'!$A$2:$A$300,0)),0) -> 0 | N11: =IFERROR(INDEX('CB3 Bar'!$F$2:$F$300,MATCH(A11,'CB3 Bar'!$A$2:$A$300,0)),0) -> 0 | O11: =IFERROR(INDEX('Spirits Room'!$F$2:$F$300,MATCH(A11,'Spirits Room'!$A$2:$A$300,0)),0) -> 0 | P11: =IFERROR(INDEX('White Wine Fridge'!$F$2:$F$300,MATCH(A11,'White Wine Fridge'!$A$2:$A$300,0)),0) -> 0 | Q11: =IFERROR(INDEX('Lower Keg'!$F$2:$F$300,MATCH(A11,'Lower Keg'!$A$2:$A$300,0)),0) -> 0 | R11: =IFERROR(INDEX('Botanical Storeroom'!$F$2:$F$300,MATCH(A11,'Botanical Storeroom'!$A$2:$A$300,0)),0) -> 0 | S11: =IFERROR(INDEX('Botanical Bar'!$F$2:$F$300,MATCH(A11,'Botanical Bar'!$A$2:$A$300,0)),0) -> 0 | T11: =IFERROR(INDEX('Loading Dock Fridge'!$F$2:$F$300,MATCH(A11,'Loading Dock Fridge'!$A$2:$A$300,0)),0) -> 0 | U11: =IFERROR(INDEX('Postmix Loading Dock'!$F$2:$F$300,MATCH(A11,'Postmix Loading Dock'!$A$2:$A$300,0)),0) -> 0 | V11: =IFERROR(INDEX('Postmix Lower Keg'!$F$2:$F$300,MATCH(A11,'Postmix Lower Keg'!$A$2:$A$300,0)),0) -> 0 | W11: =IFERROR(INDEX('Postmix TWR'!$F$2:$F$300,MATCH(A11,'Postmix TWR'!$A$2:$A$300,0)),0) -> 0
A12: 36728 | B12: BEER PACK | C12: BEER | D12: HAHN SUPER DRY 3.5pcnt 330ML CTNx24EA 3424 | E12: 24 | F12: =G12+H12+I12+J12+K12+L12+M12+N12+O12+P12+Q12+R12+S12+T12+U12+V12+W12 -> 0 | G12: =IFERROR(INDEX('Juice Fridge'!$F$2:$F$300,MATCH(A12,'Juice Fridge'!$A$2:$A$300,0)),0) -> 0 | H12: =IFERROR(INDEX('Upper Keg'!$F$2:$F$300,MATCH(A12,'Upper Keg'!$A$2:$A$300,0)),0) -> 0 | I12: =IFERROR(INDEX('Astral Bar'!$F$2:$F$300,MATCH(A12,'Astral Bar'!$A$2:$A$300,0)),0) -> 0 | J12: =IFERROR(INDEX('GB1 Bar'!$F$2:$F$300,MATCH(A12,'GB1 Bar'!$A$2:$A$300,0)),0) -> 0 | K12: =IFERROR(INDEX('GB2 Bar'!$F$2:$F$300,MATCH(A12,'GB2 Bar'!$A$2:$A$300,0)),0) -> 0 | L12: =IFERROR(INDEX('CB1 Bar'!$F$2:$F$300,MATCH(A12,'CB1 Bar'!$A$2:$A$300,0)),0) -> 0 | M12: =IFERROR(INDEX('CB2 Bar'!$F$2:$F$300,MATCH(A12,'CB2 Bar'!$A$2:$A$300,0)),0) -> 0 | N12: =IFERROR(INDEX('CB3 Bar'!$F$2:$F$300,MATCH(A12,'CB3 Bar'!$A$2:$A$300,0)),0) -> 0 | O12: =IFERROR(INDEX('Spirits Room'!$F$2:$F$300,MATCH(A12,'Spirits Room'!$A$2:$A$300,0)),0) -> 0 | P12: =IFERROR(INDEX('White Wine Fridge'!$F$2:$F$300,MATCH(A12,'White Wine Fridge'!$A$2:$A$300,0)),0) -> 0 | Q12: =IFERROR(INDEX('Lower Keg'!$F$2:$F$300,MATCH(A12,'Lower Keg'!$A$2:$A$300,0)),0) -> 0 | R12: =IFERROR(INDEX('Botanical Storeroom'!$F$2:$F$300,MATCH(A12,'Botanical Storeroom'!$A$2:$A$300,0)),0) -> 0 | S12: =IFERROR(INDEX('Botanical Bar'!$F$2:$F$300,MATCH(A12,'Botanical Bar'!$A$2:$A$300,0)),0) -> 0 | T12: =IFERROR(INDEX('Loading Dock Fridge'!$F$2:$F$300,MATCH(A12,'Loading Dock Fridge'!$A$2:$A$300,0)),0) -> 0 | U12: =IFERROR(INDEX('Postmix Loading Dock'!$F$2:$F$300,MATCH(A12,'Postmix Loading Dock'!$A$2:$A$300,0)),0) -> 0 | V12: =IFERROR(INDEX('Postmix Lower Keg'!$F$2:$F$300,MATCH(A12,'Postmix Lower Keg'!$A$2:$A$300,0)),0) -> 0 | W12: =IFERROR(INDEX('Postmix TWR'!$F$2:$F$300,MATCH(A12,'Postmix TWR'!$A$2:$A$300,0)),0) -> 0
A13: 22465 | B13: BEER PACK | C13: BEER | D13: HEINEKEN LAGER XLN STUBBIE 330ML CTNx24ea - 3096 | E13: 24 | F13: =G13+H13+I13+J13+K13+L13+M13+N13+O13+P13+Q13+R13+S13+T13+U13+V13+W13 -> 0 | G13: =IFERROR(INDEX('Juice Fridge'!$F$2:$F$300,MATCH(A13,'Juice Fridge'!$A$2:$A$300,0)),0) -> 0 | H13: =IFERROR(INDEX('Upper Keg'!$F$2:$F$300,MATCH(A13,'Upper Keg'!$A$2:$A$300,0)),0) -> 0 | I13: =IFERROR(INDEX('Astral Bar'!$F$2:$F$300,MATCH(A13,'Astral Bar'!$A$2:$A$300,0)),0) -> 0 | J13: =IFERROR(INDEX('GB1 Bar'!$F$2:$F$300,MATCH(A13,'GB1 Bar'!$A$2:$A$300,0)),0) -> 0 | K13: =IFERROR(INDEX('GB2 Bar'!$F$2:$F$300,MATCH(A13,'GB2 Bar'!$A$2:$A$300,0)),0) -> 0 | L13: =IFERROR(INDEX('CB1 Bar'!$F$2:$F$300,MATCH(A13,'CB1 Bar'!$A$2:$A$300,0)),0) -> 0 | M13: =IFERROR(INDEX('CB2 Bar'!$F$2:$F$300,MATCH(A13,'CB2 Bar'!$A$2:$A$300,0)),0) -> 0 | N13: =IFERROR(INDEX('CB3 Bar'!$F$2:$F$300,MATCH(A13,'CB3 Bar'!$A$2:$A$300,0)),0) -> 0 | O13: =IFERROR(INDEX('Spirits Room'!$F$2:$F$300,MATCH(A13,'Spirits Room'!$A$2:$A$300,0)),0) -> 0 | P13: =IFERROR(INDEX('White Wine Fridge'!$F$2:$F$300,MATCH(A13,'White Wine Fridge'!$A$2:$A$300,0)),0) -> 0 | Q13: =IFERROR(INDEX('Lower Keg'!$F$2:$F$300,MATCH(A13,'Lower Keg'!$A$2:$A$300,0)),0) -> 0 | R13: =IFERROR(INDEX('Botanical Storeroom'!$F$2:$F$300,MATCH(A13,'Botanical Storeroom'!$A$2:$A$300,0)),0) -> 0 | S13: =IFERROR(INDEX('Botanical Bar'!$F$2:$F$300,MATCH(A13,'Botanical Bar'!$A$2:$A$300,0)),0) -> 0 | T13: =IFERROR(INDEX('Loading Dock Fridge'!$F$2:$F$300,MATCH(A13,'Loading Dock Fridge'!$A$2:$A$300,0)),0) -> 0 | U13: =IFERROR(INDEX('Postmix Loading Dock'!$F$2:$F$300,MATCH(A13,'Postmix Loading Dock'!$A$2:$A$300,0)),0) -> 0 | V13: =IFERROR(INDEX('Postmix Lower Keg'!$F$2:$F$300,MATCH(A13,'Postmix Lower Keg'!$A$2:$A$300,0)),0) -> 0 | W13: =IFERROR(INDEX('Postmix TWR'!$F$2:$F$300,MATCH(A13,'Postmix TWR'!$A$2:$A$300,0)),0) -> 0
... A193: 47464 | B193: WINE WHITE OTH | C193: WHITE WINE | D193: BABICH BLACK LABEL PINOT GRIS 750ML CTNx12EA | E193: 12 | F193: =G193+H193+I193+J193+K193+L193+M193+N193+O193+P193+Q193+R193+S193+T193+U193+V193+W193 -> 0 | G193: =IFERROR(INDEX('Juice Fridge'!$F$2:$F$300,MATCH(A193,'Juice Fridge'!$A$2:$A$300,0)),0) -> 0 | H193: =IFERROR(INDEX('Upper Keg'!$F$2:$F$300,MATCH(A193,'Upper Keg'!$A$2:$A$300,0)),0) -> 0 | I193: =IFERROR(INDEX('Astral Bar'!$F$2:$F$300,MATCH(A193,'Astral Bar'!$A$2:$A$300,0)),0) -> 0 | J193: =IFERROR(INDEX('GB1 Bar'!$F$2:$F$300,MATCH(A193,'GB1 Bar'!$A$2:$A$300,0)),0) -> 0 | K193: =IFERROR(INDEX('GB2 Bar'!$F$2:$F$300,MATCH(A193,'GB2 Bar'!$A$2:$A$300,0)),0) -> 0 | L193: =IFERROR(INDEX('CB1 Bar'!$F$2:$F$300,MATCH(A193,'CB1 Bar'!$A$2:$A$300,0)),0) -> 0 | M193: =IFERROR(INDEX('CB2 Bar'!$F$2:$F$300,MATCH(A193,'CB2 Bar'!$A$2:$A$300,0)),0) -> 0 | N193: =IFERROR(INDEX('CB3 Bar'!$F$2:$F$300,MATCH(A193,'CB3 Bar'!$A$2:$A$300,0)),0) -> 0 | O193: =IFERROR(INDEX('Spirits Room'!$F$2:$F$300,MATCH(A193,'Spirits Room'!$A$2:$A$300,0)),0) -> 0 | P193: =IFERROR(INDEX('White Wine Fridge'!$F$2:$F$300,MATCH(A193,'White Wine Fridge'!$A$2:$A$300,0)),0) -> 0 | Q193: =IFERROR(INDEX('Lower Keg'!$F$2:$F$300,MATCH(A193,'Lower Keg'!$A$2:$A$300,0)),0) -> 0 | R193: =IFERROR(INDEX('Botanical Storeroom'!$F$2:$F$300,MATCH(A193,'Botanical Storeroom'!$A$2:$A$300,0)),0) -> 0 | S193: =IFERROR(INDEX('Botanical Bar'!$F$2:$F$300,MATCH(A193,'Botanical Bar'!$A$2:$A$300,0)),0) -> 0 | T193: =IFERROR(INDEX('Loading Dock Fridge'!$F$2:$F$300,MATCH(A193,'Loading Dock Fridge'!$A$2:$A$300,0)),0) -> 0 | U193: =IFERROR(INDEX('Postmix Loading Dock'!$F$2:$F$300,MATCH(A193,'Postmix Loading Dock'!$A$2:$A$300,0)),0) -> 0 | V193: =IFERROR(INDEX('Postmix Lower Keg'!$F$2:$F$300,MATCH(A193,'Postmix Lower Keg'!$A$2:$A$300,0)),0) -> 0 | W193: =IFERROR(INDEX('Postmix TWR'!$F$2:$F$300,MATCH(A193,'Postmix TWR'!$A$2:$A$300,0)),0) -> 0

Sheet Juice Fridge
A1: Barcode | B1: Sub Category | C1: Category | D1: Product Name | E1: Carton Size | F1: Total | G1: Cartons | H1: Cartons2 | I1: Cartons3 | J1: Loose | K1: Loose2 | L1: Loose3
A2: 66549 | B2: BEER AUS PACK | C2: BEER | D2: BROOKVALE GINGER BEER 330ML STUBBIE CTNx24EA | E2: 24 | F2: =SUM(Juice_Fridge[[#This Row],[Loose]]+Juice_Fridge[[#This Row],[Loose2]]+Juice_Fridge[[#This Row],[Loose3]]+(Juice_Fridge[[#This Row],[Cartons3]]*Juice_Fridge[[#This Row],[Carton Size]])+(Juice_Fridge[[#This Row],[Cartons2]]*Juice_Fridge[[#This Row],[Carton Size]])+(Juice_Fridge[[#This Row],[Cartons]]*Juice_Fridge[[#This Row],[Carton Size]])) -> 0
A3: 59237 | B3: BEER AUS PACK | C3: BEER | D3: CARLTON DRY STUBBIE 330ML CTNX24EA | E3: 24 | F3: =SUM(Juice_Fridge[[#This Row],[Loose]]+Juice_Fridge[[#This Row],[Loose2]]+Juice_Fridge[[#This Row],[Loose3]]+(Juice_Fridge[[#This Row],[Cartons3]]*Juice_Fridge[[#This Row],[Carton Size]])+(Juice_Fridge[[#This Row],[Cartons2]]*Juice_Fridge[[#This Row],[Carton Size]])+(Juice_Fridge[[#This Row],[Cartons]]*Juice_Fridge[[#This Row],[Carton Size]])) -> 0
A4: 64212 | B4: BEER AUS PACK | C4: BEER | D4: CARLTON ZERO STUBBIE 330ML CTNx24EA | E4: 24 | F4: =SUM(Juice_Fridge[[#This Row],[Loose]]+Juice_Fridge[[#This Row],[Loose2]]+Juice_Fridge[[#This Row],[Loose3]]+(Juice_Fridge[[#This Row],[Cartons3]]*Juice_Fridge[[#This Row],[Carton Size]])+(Juice_Fridge[[#This Row],[Cartons2]]*Juice_Fridge[[#This Row],[Carton Size]])+(Juice_Fridge[[#This Row],[Cartons]]*Juice_Fridge[[#This Row],[Carton Size]])) -> 0
A5: 54419 | B5: BEER AUS PACK | C5: BEER | D5: GREAT NORTHERN SUPER CRISP LAGER 330ML CTNx24EA | E5: 24 | F5: =SUM(Juice_Fridge[[#This Row],[Loose]]+Juice_Fridge[[#This Row],[Loose2]]+Juice_Fridge[[#This Row],[Loose3]]+(Juice_Fridge[[#This Row],[Cartons3]]*Juice_Fridge[[#This Row],[Carton Size]])+(Juice_Fridge[[#This Row],[Cartons2]]*Juice_Fridge[[#This Row],[Carton Size]])+(Juice_Fridge[[#This Row],[Cartons]]*Juice_Fridge[[#This Row],[Carton Size]])) -> 0
A6: 60039 | B6: BEER AUS PACK | C6: BEER | D6: HAHN ULTRA CRISP GLUTEN FREE 4.2% 330ML CTNx24EA | E6: 24 | F6: =SUM(Juice_Fridge[[#This Row],[Loose]]+Juice_Fridge[[#This Row],[Loose2]]+Juice_Fridge[[#This Row],[Loose3]]+(Juice_Fridge[[#This Row],[Cartons3]]*Juice_Fridge[[#This Row],[Carton Size]])+(Juice_Fridge[[#This Row],[Cartons2]]*Juice_Fridge[[#This Row],[Carton Size]])+(Juice_Fridge[[#This Row],[Cartons]]*Juice_Fridge[[#This Row],[Carton Size]])) -> 0
A7: 69689 | B7: BEER AUS PACK | C7: BEER | D7: SWAN DRAUGHT 375ML CAN CTN X24 | E7: 24 | F7: =SUM(Juice_Fridge[[#This Row],[Loose]]+Juice_Fridge[[#This Row],[Loose2]]+Juice_Fridge[[#This Row],[Loose3]]+(Juice_Fridge[[#This Row],[Cartons3]]*Juice_Fridge[[#This Row],[Carton Size]])+(Juice_Fridge[[#This Row],[Cartons2]]*Juice_Fridge[[#This Row],[Carton Size]])+(Juice_Fridge[[#This Row],[Cartons]]*Juice_Fridge[[#This Row],[Carton Size]])) -> 0
A8: 60612 | B8: BEER IMP PACK | C8: BEER | D8: HEINEKEN ZERO 0.0% STUBBIE 330ML CTNx24EA | E8: 24 | F8: =SUM(Juice_Fridge[[#This Row],[Loose]]+Juice_Fridge[[#This Row],[Loose2]]+Juice_Fridge[[#This Row],[Loose3]]+(Juice_Fridge[[#This Row],[Cartons3]]*Juice_Fridge[[#This Row],[Carton Size]])+(Juice_Fridge[[#This Row],[Cartons2]]*Juice_Fridge[[#This Row],[Carton Size]])+(Juice_Fridge[[#This Row],[Cartons]]*Juice_Fridge[[#This Row],[Carton Size]])) -> 0
A9: 383 | B9: BEER PACK | C9: BEER | D9: CORONA BEER 355ML CTNx24EA | E9: 24 | F9: =SUM(Juice_Fridge[[#This Row],[Loose]]+Juice_Fridge[[#This Row],[Loose2]]+Juice_Fridge[[#This Row],[Loose3]]+(Juice_Fridge[[#This Row],[Cartons3]]*Juice_Fridge[[#This Row],[Carton Size]])+(Juice_Fridge[[#This Row],[Cartons2]]*Juice_Fridge[[#This Row],[Carton Size]])+(Juice_Fridge[[#This Row],[Cartons]]*Juice_Fridge[[#This Row],[Carton Size]])) -> 0
A10: 191 | B10: BEER PACK | C10: BEER | D10: CROWN LAGER STUBBIE 24X375ML | E10: 24 | F10: =SUM(Juice_Fridge[[#This Row],[Loose]]+Juice_Fridge[[#This Row],[Loose2]]+Juice_Fridge[[#This Row],[Loose3]]+(Juice_Fridge[[#This Row],[Cartons3]]*Juice_Fridge[[#This Row],[Carton Size]])+(Juice_Fridge[[#This Row],[Cartons2]]*Juice_Fridge[[#This Row],[Carton Size]])+(Juice_Fridge[[#This Row],[Cartons]]*Juice_Fridge[[#This Row],[Carton Size]])) -> 0
A11: 116393 | B11: BEER PACK | C11: BEER | D11: HAHN LIGHT PREMIUM STUBBIE 375ML 3547 CTNx24EA | E11: 24 | F11: =SUM(Juice_Fridge[[#This Row],[Loose]]+Juice_Fridge[[#This Row],[Loose2]]+Juice_Fridge[[#This Row],[Loose3]]+(Juice_Fridge[[#This Row],[Cartons3]]*Juice_Fridge[[#This Row],[Carton Size]])+(Juice_Fridge[[#This Row],[Cartons2]]*Juice_Fridge[[#This Row],[Carton Size]])+(Juice_Fridge[[#This Row],[Cartons]]*Juice_Fridge[[#This Row],[Carton Size]])) -> 0
A12: 36728 | B12: BEER PACK | C12: BEER | D12: HAHN SUPER DRY 3.5pcnt 330ML CTNx24EA 3424 | E12: 24 | F12: =SUM(Juice_Fridge[[#This Row],[Loose]]+Juice_Fridge[[#This Row],[Loose2]]+Juice_Fridge[[#This Row],[Loose3]]+(Juice_Fridge[[#This Row],[Cartons3]]*Juice_Fridge[[#This Row],[Carton Size]])+(Juice_Fridge[[#This Row],[Cartons2]]*Juice_Fridge[[#This Row],[Carton Size]])+(Juice_Fridge[[#This Row],[Cartons]]*Juice_Fridge[[#This Row],[Carton Size]])) -> 0
A13: 22465 | B13: BEER PACK | C13: BEER | D13: HEINEKEN LAGER XLN STUBBIE 330ML CTNx24ea - 3096 | E13: 24 | F13: =SUM(Juice_Fridge[[#This Row],[Loose]]+Juice_Fridge[[#This Row],[Loose2]]+Juice_Fridge[[#This Row],[Loose3]]+(Juice_Fridge[[#This Row],[Cartons3]]*Juice_Fridge[[#This Row],[Carton Size]])+(Juice_Fridge[[#This Row],[Cartons2]]*Juice_Fridge[[#This Row],[Carton Size]])+(Juice_Fridge[[#This Row],[Cartons]]*Juice_Fridge[[#This Row],[Carton Size]])) -> 0
... A193: 47464 | B193: WINE WHITE OTH | C193: WHITE WINE | D193: BABICH BLACK LABEL PINOT GRIS 750ML CTNx12EA | E193: 12 | F193: =SUM(Juice_Fridge[[#This Row],[Loose]]+Juice_Fridge[[#This Row],[Loose2]]+Juice_Fridge[[#This Row],[Loose3]]+(Juice_Fridge[[#This Row],[Cartons3]]*Juice_Fridge[[#This Row],[Carton Size]])+(Juice_Fridge[[#This Row],[Cartons2]]*Juice_Fridge[[#This Row],[Carton Size]])+(Juice_Fridge[[#This Row],[Cartons]]*Juice_Fridge[[#This Row],[Carton Size]])) -> 0

Sheet Upper Keg
A1: Barcode | B1: Sub Category | C1: Category | D1: Product Name | E1: Carton Size | F1: Total | G1: Cartons | H1: Cartons2 | I1: Cartons3 | J1: Loose | K1: Loose2 | L1: Loose3
A2: 54419 | B2: BEER AUS PACK | C2: BEER | D2: GREAT NORTHERN SUPER CRISP LAGER 330ML CTNx24EA | E2: 24 | F2: =SUM(Upper_Keg[[#This Row],[Loose]]+Upper_Keg[[#This Row],[Loose2]]+Upper_Keg[[#This Row],[Loose3]]+(Upper_Keg[[#This Row],[Cartons3]]*Upper_Keg[[#This Row],[Carton Size]])+(Upper_Keg[[#This Row],[Cartons2]]*Upper_Keg[[#This Row],[Carton Size]])+(Upper_Keg[[#This Row],[Cartons]]*Upper_Keg[[#This Row],[Carton Size]])) -> 0
A3: 59237 | B3: BEER AUS PACK | C3: BEER | D3: CARLTON DRY STUBBIE 330ML CTNX24EA | E3: 24 | F3: =SUM(Upper_Keg[[#This Row],[Loose]]+Upper_Keg[[#This Row],[Loose2]]+Upper_Keg[[#This Row],[Loose3]]+(Upper_Keg[[#This Row],[Cartons3]]*Upper_Keg[[#This Row],[Carton Size]])+(Upper_Keg[[#This Row],[Cartons2]]*Upper_Keg[[#This Row],[Carton Size]])+(Upper_Keg[[#This Row],[Cartons]]*Upper_Keg[[#This Row],[Carton Size]])) -> 0
A4: 60039 | B4: BEER AUS PACK | C4: BEER | D4: HAHN ULTRA CRISP GLUTEN FREE 4.2% 330ML CTNx24EA | E4: 24 | F4: =SUM(Upper_Keg[[#This Row],[Loose]]+Upper_Keg[[#This Row],[Loose2]]+Upper_Keg[[#This Row],[Loose3]]+(Upper_Keg[[#This Row],[Cartons3]]*Upper_Keg[[#This Row],[Carton Size]])+(Upper_Keg[[#This Row],[Cartons2]]*Upper_Keg[[#This Row],[Carton Size]])+(Upper_Keg[[#This Row],[Cartons]]*Upper_Keg[[#This Row],[Carton Size]])) -> 0
A5: 64212 | B5: BEER AUS PACK | C5: BEER | D5: CARLTON ZERO STUBBIE 330ML CTNx24EA | E5: 24 | F5: =SUM(Upper_Keg[[#This Row],[Loose]]+Upper_Keg[[#This Row],[Loose2]]+Upper_Keg[[#This Row],[Loose3]]+(Upper_Keg[[#This Row],[Cartons3]]*Upper_Keg[[#This Row],[Carton Size]])+(Upper_Keg[[#This Row],[Cartons2]]*Upper_Keg[[#This Row],[Carton Size]])+(Upper_Keg[[#This Row],[Cartons]]*Upper_Keg[[#This Row],[Carton Size]])) -> 0
A6: 66549 | B6: BEER AUS PACK | C6: BEER | D6: BROOKVALE GINGER BEER 330ML STUBBIE CTNx24EA | E6: 24 | F6: =SUM(Upper_Keg[[#This Row],[Loose]]+Upper_Keg[[#This Row],[Loose2]]+Upper_Keg[[#This Row],[Loose3]]+(Upper_Keg[[#This Row],[Cartons3]]*Upper_Keg[[#This Row],[Carton Size]])+(Upper_Keg[[#This Row],[Cartons2]]*Upper_Keg[[#This Row],[Carton Size]])+(Upper_Keg[[#This Row],[Cartons]]*Upper_Keg[[#This Row],[Carton Size]])) -> 0
A7: 69689 | B7: BEER AUS PACK | C7: BEER | D7: SWAN DRAUGHT 375ML CAN CTN X24 | E7: 24 | F7: =SUM(Upper_Keg[[#This Row],[Loose]]+Upper_Keg[[#This Row],[Loose2]]+Upper_Keg[[#This Row],[Loose3]]+(Upper_Keg[[#This Row],[Cartons3]]*Upper_Keg[[#This Row],[Carton Size]])+(Upper_Keg[[#This Row],[Cartons2]]*Upper_Keg[[#This Row],[Carton Size]])+(Upper_Keg[[#This Row],[Cartons]]*Upper_Keg[[#This Row],[Carton Size]])) -> 0
A8: 60612 | B8: BEER IMP PACK | C8: BEER | D8: HEINEKEN ZERO 0.0% STUBBIE 330ML CTNx24EA | E8: 24 | F8: =SUM(Upper_Keg[[#This Row],[Loose]]+Upper_Keg[[#This Row],[Loose2]]+Upper_Keg[[#This Row],[Loose3]]+(Upper_Keg[[#This Row],[Cartons3]]*Upper_Keg[[#This Row],[Carton Size]])+(Upper_Keg[[#This Row],[Cartons2]]*Upper_Keg[[#This Row],[Carton Size]])+(Upper_Keg[[#This Row],[Cartons]]*Upper_Keg[[#This Row],[Carton Size]])) -> 0
A9: 191 | B9: BEER PACK | C9: BEER | D9: CROWN LAGER STUBBIE 24X375ML | E9: 24 | F9: =SUM(Upper_Keg[[#This Row],[Loose]]+Upper_Keg[[#This Row],[Loose2]]+Upper_Keg[[#This Row],[Loose3]]+(Upper_Keg[[#This Row],[Cartons3]]*Upper_Keg[[#This Row],[Carton Size]])+(Upper_Keg[[#This Row],[Cartons2]]*Upper_Keg[[#This Row],[Carton Size]])+(Upper_Keg[[#This Row],[Cartons]]*Upper_Keg[[#This Row],[Carton Size]])) -> 0
A10: 383 | B10: BEER PACK | C10: BEER | D10: CORONA BEER 355ML CTNx24EA | E10: 24 | F10: =SUM(Upper_Keg[[#This Row],[Loose]]+Upper_Keg[[#This Row],[Loose2]]+Upper_Keg[[#This Row],[Loose3]]+(Upper_Keg[[#This Row],[Cartons3]]*Upper_Keg[[#This Row],[Carton Size]])+(Upper_Keg[[#This Row],[Cartons2]]*Upper_Keg[[#This Row],[Carton Size]])+(Upper_Keg[[#This Row],[Cartons]]*Upper_Keg[[#This Row],[Carton Size]])) -> 0
A11: 22465 | B11: BEER PACK | C11: BEER | D11: HEINEKEN LAGER XLN STUBBIE 330ML CTNx24ea - 3096 | E11: 24 | F11: =SUM(Upper_Keg[[#This Row],[Loose]]+Upper_Keg[[#This Row],[Loose2]]+Upper_Keg[[#This Row],[Loose3]]+(Upper_Keg[[#This Row],[Cartons3]]*Upper_Keg[[#This Row],[Carton Size]])+(Upper_Keg[[#This Row],[Cartons2]]*Upper_Keg[[#This Row],[Carton Size]])+(Upper_Keg[[#This Row],[Cartons]]*Upper_Keg[[#This Row],[Carton Size]])) -> 0
A12: 24115 | B12: BEER PACK | C12: BEER | D12: LITTLE CREATURES PALE ALE 330ML 574046 | E12: 24 | F12: =SUM(Upper_Keg[[#This Row],[Loose]]+Upper_Keg[[#This Row],[Loose2]]+Upper_Keg[[#This Row],[Loose3]]+(Upper_Keg[[#This Row],[Cartons3]]*Upper_Keg[[#This Row],[Carton Size]])+(Upper_Keg[[#This Row],[Cartons2]]*Upper_Keg[[#This Row],[Carton Size]])+(Upper_Keg[[#This Row],[Cartons]]*Upper_Keg[[#This Row],[Carton Size]])) -> 0
A13: 32471 | B13: BEER PACK | C13: BEER | D13: LITTLE CREATURES ROGERS AMBER ALE 330ML 574070 CTNx24EA | E13: 24 | F13: =SUM(Upper_Keg[[#This Row],[Loose]]+Upper_Keg[[#This Row],[Loose2]]+Upper_Keg[[#This Row],[Loose3]]+(Upper_Keg[[#This Row],[Cartons3]]*Upper_Keg[[#This Row],[Carton Size]])+(Upper_Keg[[#This Row],[Cartons2]]*Upper_Keg[[#This Row],[Carton Size]])+(Upper_Keg[[#This Row],[Cartons]]*Upper_Keg[[#This Row],[Carton Size]])) -> 0
... A193: 47464 | B193: WINE WHITE OTH | C193: WHITE WINE | D193: BABICH BLACK LABEL PINOT GRIS 750ML CTNx12EA | E193: 12 | F193: =SUM(Upper_Keg[[#This Row],[Loose]]+Upper_Keg[[#This Row],[Loose2]]+Upper_Keg[[#This Row],[Loose3]]+(Upper_Keg[[#This Row],[Cartons3]]*Upper_Keg[[#This Row],[Carton Size]])+(Upper_Keg[[#This Row],[Cartons2]]*Upper_Keg[[#This Row],[Carton Size]])+(Upper_Keg[[#This Row],[Cartons]]*Upper_Keg[[#This Row],[Carton Size]])) -> 0

Sheet Astral Bar
A1: Barcode | B1: Sub Category | C1: Category | D1: Product Name | E1: Carton Size | F1: Total | G1: Cartons | H1: Cartons2 | I1: Cartons3 | J1: Loose | K1: Loose2 | L1: Loose3
A2: 66549 | B2: BEER AUS PACK | C2: BEER | D2: BROOKVALE GINGER BEER 330ML STUBBIE CTNx24EA | E2: 24 | F2: =SUM(Upper_Keg6[[#This Row],[Loose]]+Upper_Keg6[[#This Row],[Loose2]]+Upper_Keg6[[#This Row],[Loose3]]+(Upper_Keg6[[#This Row],[Cartons3]]*Upper_Keg6[[#This Row],[Carton Size]])+(Upper_Keg6[[#This Row],[Cartons2]]*Upper_Keg6[[#This Row],[Carton Size]])+(Upper_Keg6[[#This Row],[Cartons]]*Upper_Keg6[[#This Row],[Carton Size]])) -> 0
A3: 59237 | B3: BEER AUS PACK | C3: BEER | D3: CARLTON DRY STUBBIE 330ML CTNX24EA | E3: 24 | F3: =SUM(Upper_Keg6[[#This Row],[Loose]]+Upper_Keg6[[#This Row],[Loose2]]+Upper_Keg6[[#This Row],[Loose3]]+(Upper_Keg6[[#This Row],[Cartons3]]*Upper_Keg6[[#This Row],[Carton Size]])+(Upper_Keg6[[#This Row],[Cartons2]]*Upper_Keg6[[#This Row],[Carton Size]])+(Upper_Keg6[[#This Row],[Cartons]]*Upper_Keg6[[#This Row],[Carton Size]])) -> 0
A4: 64212 | B4: BEER AUS PACK | C4: BEER | D4: CARLTON ZERO STUBBIE 330ML CTNx24EA | E4: 24 | F4: =SUM(Upper_Keg6[[#This Row],[Loose]]+Upper_Keg6[[#This Row],[Loose2]]+Upper_Keg6[[#This Row],[Loose3]]+(Upper_Keg6[[#This Row],[Cartons3]]*Upper_Keg6[[#This Row],[Carton Size]])+(Upper_Keg6[[#This Row],[Cartons2]]*Upper_Keg6[[#This Row],[Carton Size]])+(Upper_Keg6[[#This Row],[Cartons]]*Upper_Keg6[[#This Row],[Carton Size]])) -> 0
A5: 54419 | B5: BEER AUS PACK | C5: BEER | D5: GREAT NORTHERN SUPER CRISP LAGER 330ML CTNx24EA | E5: 24 | F5: =SUM(Upper_Keg6[[#This Row],[Loose]]+Upper_Keg6[[#This Row],[Loose2]]+Upper_Keg6[[#This Row],[Loose3]]+(Upper_Keg6[[#This Row],[Cartons3]]*Upper_Keg6[[#This Row],[Carton Size]])+(Upper_Keg6[[#This Row],[Cartons2]]*Upper_Keg6[[#This Row],[Carton Size]])+(Upper_Keg6[[#This Row],[Cartons]]*Upper_Keg6[[#This Row],[Carton Size]])) -> 0
A6: 60039 | B6: BEER AUS PACK | C6: BEER | D6: HAHN ULTRA CRISP GLUTEN FREE 4.2% 330ML CTNx24EA | E6: 24 | F6: =SUM(Upper_Keg6[[#This Row],[Loose]]+Upper_Keg6[[#This Row],[Loose2]]+Upper_Keg6[[#This Row],[Loose3]]+(Upper_Keg6[[#This Row],[Cartons3]]*Upper_Keg6[[#This Row],[Carton Size]])+(Upper_Keg6[[#This Row],[Cartons2]]*Upper_Keg6[[#This Row],[Carton Size]])+(Upper_Keg6[[#This Row],[Cartons]]*Upper_Keg6[[#This Row],[Carton Size]])) -> 0
A7: 69689 | B7: BEER AUS PACK | C7: BEER | D7: SWAN DRAUGHT 375ML CAN CTN X24 | E7: 24 | F7: =SUM(Upper_Keg6[[#This Row],[Loose]]+Upper_Keg6[[#This Row],[Loose2]]+Upper_Keg6[[#This Row],[Loose3]]+(Upper_Keg6[[#This Row],[Cartons3]]*Upper_Keg6[[#This Row],[Carton Size]])+(Upper_Keg6[[#This Row],[Cartons2]]*Upper_Keg6[[#This Row],[Carton Size]])+(Upper_Keg6[[#This Row],[Cartons]]*Upper_Keg6[[#This Row],[Carton Size]])) -> 0
A8: 60612 | B8: BEER IMP PACK | C8: BEER | D8: HEINEKEN ZERO 0.0% STUBBIE 330ML CTNx24EA | E8: 24 | F8: =SUM(Upper_Keg6[[#This Row],[Loose]]+Upper_Keg6[[#This Row],[Loose2]]+Upper_Keg6[[#This Row],[Loose3]]+(Upper_Keg6[[#This Row],[Cartons3]]*Upper_Keg6[[#This Row],[Carton Size]])+(Upper_Keg6[[#This Row],[Cartons2]]*Upper_Keg6[[#This Row],[Carton Size]])+(Upper_Keg6[[#This Row],[Cartons]]*Upper_Keg6[[#This Row],[Carton Size]])) -> 0
A9: 383 | B9: BEER PACK | C9: BEER | D9: CORONA BEER 355ML CTNx24EA | E9: 24 | F9: =SUM(Upper_Keg6[[#This Row],[Loose]]+Upper_Keg6[[#This Row],[Loose2]]+Upper_Keg6[[#This Row],[Loose3]]+(Upper_Keg6[[#This Row],[Cartons3]]*Upper_Keg6[[#This Row],[Carton Size]])+(Upper_Keg6[[#This Row],[Cartons2]]*Upper_Keg6[[#This Row],[Carton Size]])+(Upper_Keg6[[#This Row],[Cartons]]*Upper_Keg6[[#This Row],[Carton Size]])) -> 0
A10: 191 | B10: BEER PACK | C10: BEER | D10: CROWN LAGER STUBBIE 24X375ML | E10: 24 | F10: =SUM(Upper_Keg6[[#This Row],[Loose]]+Upper_Keg6[[#This Row],[Loose2]]+Upper_Keg6[[#This Row],[Loose3]]+(Upper_Keg6[[#This Row],[Cartons3]]*Upper_Keg6[[#This Row],[Carton Size]])+(Upper_Keg6[[#This Row],[Cartons2]]*Upper_Keg6[[#This Row],[Carton Size]])+(Upper_Keg6[[#This Row],[Cartons]]*Upper_Keg6[[#This Row],[Carton Size]])) -> 0
A11: 116393 | B11: BEER PACK | C11: BEER | D11: HAHN LIGHT PREMIUM STUBBIE 375ML 3547 CTNx24EA | E11: 24 | F11: =SUM(Upper_Keg6[[#This Row],[Loose]]+Upper_Keg6[[#This Row],[Loose2]]+Upper_Keg6[[#This Row],[Loose3]]+(Upper_Keg6[[#This Row],[Cartons3]]*Upper_Keg6[[#This Row],[Carton Size]])+(Upper_Keg6[[#This Row],[Cartons2]]*Upper_Keg6[[#This Row],[Carton Size]])+(Upper_Keg6[[#This Row],[Cartons]]*Upper_Keg6[[#This Row],[Carton Size]])) -> 0
A12: 36728 | B12: BEER PACK | C12: BEER | D12: HAHN SUPER DRY 3.5pcnt 330ML CTNx24EA 3424 | E12: 24 | F12: =SUM(Upper_Keg6[[#This Row],[Loose]]+Upper_Keg6[[#This Row],[Loose2]]+Upper_Keg6[[#This Row],[Loose3]]+(Upper_Keg6[[#This Row],[Cartons3]]*Upper_Keg6[[#This Row],[Carton Size]])+(Upper_Keg6[[#This Row],[Cartons2]]*Upper_Keg6[[#This Row],[Carton Size]])+(Upper_Keg6[[#This Row],[Cartons]]*Upper_Keg6[[#This Row],[Carton Size]])) -> 0
A13: 22465 | B13: BEER PACK | C13: BEER | D13: HEINEKEN LAGER XLN STUBBIE 330ML CTNx24ea - 3096 | E13: 24 | F13: =SUM(Upper_Keg6[[#This Row],[Loose]]+Upper_Keg6[[#This Row],[Loose2]]+Upper_Keg6[[#This Row],[Loose3]]+(Upper_Keg6[[#This Row],[Cartons3]]*Upper_Keg6[[#This Row],[Carton Size]])+(Upper_Keg6[[#This Row],[Cartons2]]*Upper_Keg6[[#This Row],[Carton Size]])+(Upper_Keg6[[#This Row],[Cartons]]*Upper_Keg6[[#This Row],[Carton Size]])) -> 0
... A193: 47464 | B193: WINE WHITE OTH | C193: WHITE WINE | D193: BABICH BLACK LABEL PINOT GRIS 750ML CTNx12EA | E193: 12 | F193: =SUM(Upper_Keg6[[#This Row],[Loose]]+Upper_Keg6[[#This Row],[Loose2]]+Upper_Keg6[[#This Row],[Loose3]]+(Upper_Keg6[[#This Row],[Cartons3]]*Upper_Keg6[[#This Row],[Carton Size]])+(Upper_Keg6[[#This Row],[Cartons2]]*Upper_Keg6[[#This Row],[Carton Size]])+(Upper_Keg6[[#This Row],[Cartons]]*Upper_Keg6[[#This Row],[Carton Size]])) -> 0

Sheet GB1 Bar
A1: Barcode | B1: Sub Category | C1: Category | D1: Product Name | E1: Carton Size | F1: Total | G1: Cartons | H1: Cartons2 | I1: Cartons3 | J1: Loose | K1: Loose2 | L1: Loose3
A2: 66549 | B2: BEER AUS PACK | C2: BEER | D2: BROOKVALE GINGER BEER 330ML STUBBIE CTNx24EA | E2: 24 | F2: =SUM(GB1_Bar[[#This Row],[Loose]]+GB1_Bar[[#This Row],[Loose2]]+GB1_Bar[[#This Row],[Loose3]]+(GB1_Bar[[#This Row],[Cartons3]]*GB1_Bar[[#This Row],[Carton Size]])+(GB1_Bar[[#This Row],[Cartons2]]*GB1_Bar[[#This Row],[Carton Size]])+(GB1_Bar[[#This Row],[Cartons]]*GB1_Bar[[#This Row],[Carton Size]])) -> 0
A3: 59237 | B3: BEER AUS PACK | C3: BEER | D3: CARLTON DRY STUBBIE 330ML CTNX24EA | E3: 24 | F3: =SUM(GB1_Bar[[#This Row],[Loose]]+GB1_Bar[[#This Row],[Loose2]]+GB1_Bar[[#This Row],[Loose3]]+(GB1_Bar[[#This Row],[Cartons3]]*GB1_Bar[[#This Row],[Carton Size]])+(GB1_Bar[[#This Row],[Cartons2]]*GB1_Bar[[#This Row],[Carton Size]])+(GB1_Bar[[#This Row],[Cartons]]*GB1_Bar[[#This Row],[Carton Size]])) -> 0
A4: 64212 | B4: BEER AUS PACK | C4: BEER | D4: CARLTON ZERO STUBBIE 330ML CTNx24EA | E4: 24 | F4: =SUM(GB1_Bar[[#This Row],[Loose]]+GB1_Bar[[#This Row],[Loose2]]+GB1_Bar[[#This Row],[Loose3]]+(GB1_Bar[[#This Row],[Cartons3]]*GB1_Bar[[#This Row],[Carton Size]])+(GB1_Bar[[#This Row],[Cartons2]]*GB1_Bar[[#This Row],[Carton Size]])+(GB1_Bar[[#This Row],[Cartons]]*GB1_Bar[[#This Row],[Carton Size]])) -> 0
A5: 54419 | B5: BEER AUS PACK | C5: BEER | D5: GREAT NORTHERN SUPER CRISP LAGER 330ML CTNx24EA | E5: 24 | F5: =SUM(GB1_Bar[[#This Row],[Loose]]+GB1_Bar[[#This Row],[Loose2]]+GB1_Bar[[#This Row],[Loose3]]+(GB1_Bar[[#This Row],[Cartons3]]*GB1_Bar[[#This Row],[Carton Size]])+(GB1_Bar[[#This Row],[Cartons2]]*GB1_Bar[[#This Row],[Carton Size]])+(GB1_Bar[[#This Row],[Cartons]]*GB1_Bar[[#This Row],[Carton Size]])) -> 0
A6: 60039 | B6: BEER AUS PACK | C6: BEER | D6: HAHN ULTRA CRISP GLUTEN FREE 4.2% 330ML CTNx24EA | E6: 24 | F6: =SUM(GB1_Bar[[#This Row],[Loose]]+GB1_Bar[[#This Row],[Loose2]]+GB1_Bar[[#This Row],[Loose3]]+(GB1_Bar[[#This Row],[Cartons3]]*GB1_Bar[[#This Row],[Carton Size]])+(GB1_Bar[[#This Row],[Cartons2]]*GB1_Bar[[#This Row],[Carton Size]])+(GB1_Bar[[#This Row],[Cartons]]*GB1_Bar[[#This Row],[Carton Size]])) -> 0
A7: 69689 | B7: BEER AUS PACK | C7: BEER | D7: SWAN DRAUGHT 375ML CAN CTN X24 | E7: 24 | F7: =SUM(GB1_Bar[[#This Row],[Loose]]+GB1_Bar[[#This Row],[Loose2]]+GB1_Bar[[#This Row],[Loose3]]+(GB1_Bar[[#This Row],[Cartons3]]*GB1_Bar[[#This Row],[Carton Size]])+(GB1_Bar[[#This Row],[Cartons2]]*GB1_Bar[[#This Row],[Carton Size]])+(GB1_Bar[[#This Row],[Cartons]]*GB1_Bar[[#This Row],[Carton Size]])) -> 0
A8: 60612 | B8: BEER IMP PACK | C8: BEER | D8: HEINEKEN ZERO 0.0% STUBBIE 330ML CTNx24EA | E8: 24 | F8: =SUM(GB1_Bar[[#This Row],[Loose]]+GB1_Bar[[#This Row],[Loose2]]+GB1_Bar[[#This Row],[Loose3]]+(GB1_Bar[[#This Row],[Cartons3]]*GB1_Bar[[#This Row],[Carton Size]])+(GB1_Bar[[#This Row],[Cartons2]]*GB1_Bar[[#This Row],[Carton Size]])+(GB1_Bar[[#This Row],[Cartons]]*GB1_Bar[[#This Row],[Carton Size]])) -> 0
A9: 383 | B9: BEER PACK | C9: BEER | D9: CORONA BEER 355ML CTNx24EA | E9: 24 | F9: =SUM(GB1_Bar[[#This Row],[Loose]]+GB1_Bar[[#This Row],[Loose2]]+GB1_Bar[[#This Row],[Loose3]]+(GB1_Bar[[#This Row],[Cartons3]]*GB1_Bar[[#This Row],[Carton Size]])+(GB1_Bar[[#This Row],[Cartons2]]*GB1_Bar[[#This Row],[Carton Size]])+(GB1_Bar[[#This Row],[Cartons]]*GB1_Bar[[#This Row],[Carton Size]])) -> 0
A10: 191 | B10: BEER PACK | C10: BEER | D10: CROWN LAGER STUBBIE 24X375ML | E10: 24 | F10: =SUM(GB1_Bar[[#This Row],[Loose]]+GB1_Bar[[#This Row],[Loose2]]+GB1_Bar[[#This Row],[Loose3]]+(GB1_Bar[[#This Row],[Cartons3]]*GB1_Bar[[#This Row],[Carton Size]])+(GB1_Bar[[#This Row],[Cartons2]]*GB1_Bar[[#This Row],[Carton Size]])+(GB1_Bar[[#This Row],[Cartons]]*GB1_Bar[[#This Row],[Carton Size]])) -> 0
A11: 116393 | B11: BEER PACK | C11: BEER | D11: HAHN LIGHT PREMIUM STUBBIE 375ML 3547 CTNx24EA | E11: 24 | F11: =SUM(GB1_Bar[[#This Row],[Loose]]+GB1_Bar[[#This Row],[Loose2]]+GB1_Bar[[#This Row],[Loose3]]+(GB1_Bar[[#This Row],[Cartons3]]*GB1_Bar[[#This Row],[Carton Size]])+(GB1_Bar[[#This Row],[Cartons2]]*GB1_Bar[[#This Row],[Carton Size]])+(GB1_Bar[[#This Row],[Cartons]]*GB1_Bar[[#This Row],[Carton Size]])) -> 0
A12: 36728 | B12: BEER PACK | C12: BEER | D12: HAHN SUPER DRY 3.5pcnt 330ML CTNx24EA 3424 | E12: 24 | F12: =SUM(GB1_Bar[[#This Row],[Loose]]+GB1_Bar[[#This Row],[Loose2]]+GB1_Bar[[#This Row],[Loose3]]+(GB1_Bar[[#This Row],[Cartons3]]*GB1_Bar[[#This Row],[Carton Size]])+(GB1_Bar[[#This Row],[Cartons2]]*GB1_Bar[[#This Row],[Carton Size]])+(GB1_Bar[[#This Row],[Cartons]]*GB1_Bar[[#This Row],[Carton Size]])) -> 0
A13: 22465 | B13: BEER PACK | C13: BEER | D13: HEINEKEN LAGER XLN STUBBIE 330ML CTNx24ea - 3096 | E13: 24 | F13: =SUM(GB1_Bar[[#This Row],[Loose]]+GB1_Bar[[#This Row],[Loose2]]+GB1_Bar[[#This Row],[Loose3]]+(GB1_Bar[[#This Row],[Cartons3]]*GB1_Bar[[#This Row],[Carton Size]])+(GB1_Bar[[#This Row],[Cartons2]]*GB1_Bar[[#This Row],[Carton Size]])+(GB1_Bar[[#This Row],[Cartons]]*GB1_Bar[[#This Row],[Carton Size]])) -> 0
... A193: 47464 | B193: WINE WHITE OTH | C193: WHITE WINE | D193: BABICH BLACK LABEL PINOT GRIS 750ML CTNx12EA | E193: 12 | F193: =SUM(GB1_Bar[[#This Row],[Loose]]+GB1_Bar[[#This Row],[Loose2]]+GB1_Bar[[#This Row],[Loose3]]+(GB1_Bar[[#This Row],[Cartons3]]*GB1_Bar[[#This Row],[Carton Size]])+(GB1_Bar[[#This Row],[Cartons2]]*GB1_Bar[[#This Row],[Carton Size]])+(GB1_Bar[[#This Row],[Cartons]]*GB1_Bar[[#This Row],[Carton Size]])) -> 0

Sheet GB2 Bar
A1: Barcode | B1: Sub Category | C1: Category | D1: Product Name | E1: Carton Size | F1: Total | G1: Cartons | H1: Cartons2 | I1: Cartons3 | J1: Loose | K1: Loose2 | L1: Loose3
A2: 66549 | B2: BEER AUS PACK | C2: BEER | D2: BROOKVALE GINGER BEER 330ML STUBBIE CTNx24EA | E2: 24 | F2: =SUM(GB2_Bar[[#This Row],[Loose]]+GB2_Bar[[#This Row],[Loose2]]+GB2_Bar[[#This Row],[Loose3]]+(GB2_Bar[[#This Row],[Cartons3]]*GB2_Bar[[#This Row],[Carton Size]])+(GB2_Bar[[#This Row],[Cartons2]]*GB2_Bar[[#This Row],[Carton Size]])+(GB2_Bar[[#This Row],[Cartons]]*GB2_Bar[[#This Row],[Carton Size]])) -> 0
A3: 59237 | B3: BEER AUS PACK | C3: BEER | D3: CARLTON DRY STUBBIE 330ML CTNX24EA | E3: 24 | F3: =SUM(GB2_Bar[[#This Row],[Loose]]+GB2_Bar[[#This Row],[Loose2]]+GB2_Bar[[#This Row],[Loose3]]+(GB2_Bar[[#This Row],[Cartons3]]*GB2_Bar[[#This Row],[Carton Size]])+(GB2_Bar[[#This Row],[Cartons2]]*GB2_Bar[[#This Row],[Carton Size]])+(GB2_Bar[[#This Row],[Cartons]]*GB2_Bar[[#This Row],[Carton Size]])) -> 0
A4: 64212 | B4: BEER AUS PACK | C4: BEER | D4: CARLTON ZERO STUBBIE 330ML CTNx24EA | E4: 24 | F4: =SUM(GB2_Bar[[#This Row],[Loose]]+GB2_Bar[[#This Row],[Loose2]]+GB2_Bar[[#This Row],[Loose3]]+(GB2_Bar[[#This Row],[Cartons3]]*GB2_Bar[[#This Row],[Carton Size]])+(GB2_Bar[[#This Row],[Cartons2]]*GB2_Bar[[#This Row],[Carton Size]])+(GB2_Bar[[#This Row],[Cartons]]*GB2_Bar[[#This Row],[Carton Size]])) -> 0
A5: 54419 | B5: BEER AUS PACK | C5: BEER | D5: GREAT NORTHERN SUPER CRISP LAGER 330ML CTNx24EA | E5: 24 | F5: =SUM(GB2_Bar[[#This Row],[Loose]]+GB2_Bar[[#This Row],[Loose2]]+GB2_Bar[[#This Row],[Loose3]]+(GB2_Bar[[#This Row],[Cartons3]]*GB2_Bar[[#This Row],[Carton Size]])+(GB2_Bar[[#This Row],[Cartons2]]*GB2_Bar[[#This Row],[Carton Size]])+(GB2_Bar[[#This Row],[Cartons]]*GB2_Bar[[#This Row],[Carton Size]])) -> 0
A6: 60039 | B6: BEER AUS PACK | C6: BEER | D6: HAHN ULTRA CRISP GLUTEN FREE 4.2% 330ML CTNx24EA | E6: 24 | F6: =SUM(GB2_Bar[[#This Row],[Loose]]+GB2_Bar[[#This Row],[Loose2]]+GB2_Bar[[#This Row],[Loose3]]+(GB2_Bar[[#This Row],[Cartons3]]*GB2_Bar[[#This Row],[Carton Size]])+(GB2_Bar[[#This Row],[Cartons2]]*GB2_Bar[[#This Row],[Carton Size]])+(GB2_Bar[[#This Row],[Cartons]]*GB2_Bar[[#This Row],[Carton Size]])) -> 0
A7: 69689 | B7: BEER AUS PACK | C7: BEER | D7: SWAN DRAUGHT 375ML CAN CTN X24 | E7: 24 | F7: =SUM(GB2_Bar[[#This Row],[Loose]]+GB2_Bar[[#This Row],[Loose2]]+GB2_Bar[[#This Row],[Loose3]]+(GB2_Bar[[#This Row],[Cartons3]]*GB2_Bar[[#This Row],[Carton Size]])+(GB2_Bar[[#This Row],[Cartons2]]*GB2_Bar[[#This Row],[Carton Size]])+(GB2_Bar[[#This Row],[Cartons]]*GB2_Bar[[#This Row],[Carton Size]])) -> 0
A8: 60612 | B8: BEER IMP PACK | C8: BEER | D8: HEINEKEN ZERO 0.0% STUBBIE 330ML CTNx24EA | E8: 24 | F8: =SUM(GB2_Bar[[#This Row],[Loose]]+GB2_Bar[[#This Row],[Loose2]]+GB2_Bar[[#This Row],[Loose3]]+(GB2_Bar[[#This Row],[Cartons3]]*GB2_Bar[[#This Row],[Carton Size]])+(GB2_Bar[[#This Row],[Cartons2]]*GB2_Bar[[#This Row],[Carton Size]])+(GB2_Bar[[#This Row],[Cartons]]*GB2_Bar[[#This Row],[Carton Size]])) -> 0
A9: 383 | B9: BEER PACK | C9: BEER | D9: CORONA BEER 355ML CTNx24EA | E9: 24 | F9: =SUM(GB2_Bar[[#This Row],[Loose]]+GB2_Bar[[#This Row],[Loose2]]+GB2_Bar[[#This Row],[Loose3]]+(GB2_Bar[[#This Row],[Cartons3]]*GB2_Bar[[#This Row],[Carton Size]])+(GB2_Bar[[#This Row],[Cartons2]]*GB2_Bar[[#This Row],[Carton Size]])+(GB2_Bar[[#This Row],[Cartons]]*GB2_Bar[[#This Row],[Carton Size]])) -> 0
A10: 191 | B10: BEER PACK | C10: BEER | D10: CROWN LAGER STUBBIE 24X375ML | E10: 24 | F10: =SUM(GB2_Bar[[#This Row],[Loose]]+GB2_Bar[[#This Row],[Loose2]]+GB2_Bar[[#This Row],[Loose3]]+(GB2_Bar[[#This Row],[Cartons3]]*GB2_Bar[[#This Row],[Carton Size]])+(GB2_Bar[[#This Row],[Cartons2]]*GB2_Bar[[#This Row],[Carton Size]])+(GB2_Bar[[#This Row],[Cartons]]*GB2_Bar[[#This Row],[Carton Size]])) -> 0
A11: 116393 | B11: BEER PACK | C11: BEER | D11: HAHN LIGHT PREMIUM STUBBIE 375ML 3547 CTNx24EA | E11: 24 | F11: =SUM(GB2_Bar[[#This Row],[Loose]]+GB2_Bar[[#This Row],[Loose2]]+GB2_Bar[[#This Row],[Loose3]]+(GB2_Bar[[#This Row],[Cartons3]]*GB2_Bar[[#This Row],[Carton Size]])+(GB2_Bar[[#This Row],[Cartons2]]*GB2_Bar[[#This Row],[Carton Size]])+(GB2_Bar[[#This Row],[Cartons]]*GB2_Bar[[#This Row],[Carton Size]])) -> 0
A12: 36728 | B12: BEER PACK | C12: BEER | D12: HAHN SUPER DRY 3.5pcnt 330ML CTNx24EA 3424 | E12: 24 | F12: =SUM(GB2_Bar[[#This Row],[Loose]]+GB2_Bar[[#This Row],[Loose2]]+GB2_Bar[[#This Row],[Loose3]]+(GB2_Bar[[#This Row],[Cartons3]]*GB2_Bar[[#This Row],[Carton Size]])+(GB2_Bar[[#This Row],[Cartons2]]*GB2_Bar[[#This Row],[Carton Size]])+(GB2_Bar[[#This Row],[Cartons]]*GB2_Bar[[#This Row],[Carton Size]])) -> 0
A13: 22465 | B13: BEER PACK | C13: BEER | D13: HEINEKEN LAGER XLN STUBBIE 330ML CTNx24ea - 3096 | E13: 24 | F13: =SUM(GB2_Bar[[#This Row],[Loose]]+GB2_Bar[[#This Row],[Loose2]]+GB2_Bar[[#This Row],[Loose3]]+(GB2_Bar[[#This Row],[Cartons3]]*GB2_Bar[[#This Row],[Carton Size]])+(GB2_Bar[[#This Row],[Cartons2]]*GB2_Bar[[#This Row],[Carton Size]])+(GB2_Bar[[#This Row],[Cartons]]*GB2_Bar[[#This Row],[Carton Size]])) -> 0
... A193: 47464 | B193: WINE WHITE OTH | C193: WHITE WINE | D193: BABICH BLACK LABEL PINOT GRIS 750ML CTNx12EA | E193: 12 | F193: =SUM(GB2_Bar[[#This Row],[Loose]]+GB2_Bar[[#This Row],[Loose2]]+GB2_Bar[[#This Row],[Loose3]]+(GB2_Bar[[#This Row],[Cartons3]]*GB2_Bar[[#This Row],[Carton Size]])+(GB2_Bar[[#This Row],[Cartons2]]*GB2_Bar[[#This Row],[Carton Size]])+(GB2_Bar[[#This Row],[Cartons]]*GB2_Bar[[#This Row],[Carton Size]])) -> 0

Sheet CB1 Bar
A1: Barcode | B1: Sub Category | C1: Category | D1: Product Name | E1: Carton Size | F1: Total | G1: Cartons | H1: Cartons2 | I1: Cartons3 | J1: Loose | K1: Loose2 | L1: Loose3
A2: 66549 | B2: BEER AUS PACK | C2: BEER | D2: BROOKVALE GINGER BEER 330ML STUBBIE CTNx24EA | E2: 24 | F2: =SUM(CB1_Bar[[#This Row],[Loose]]+CB1_Bar[[#This Row],[Loose2]]+CB1_Bar[[#This Row],[Loose3]]+(CB1_Bar[[#This Row],[Cartons3]]*CB1_Bar[[#This Row],[Carton Size]])+(CB1_Bar[[#This Row],[Cartons2]]*CB1_Bar[[#This Row],[Carton Size]])+(CB1_Bar[[#This Row],[Cartons]]*CB1_Bar[[#This Row],[Carton Size]])) -> 0
A3: 59237 | B3: BEER AUS PACK | C3: BEER | D3: CARLTON DRY STUBBIE 330ML CTNX24EA | E3: 24 | F3: =SUM(CB1_Bar[[#This Row],[Loose]]+CB1_Bar[[#This Row],[Loose2]]+CB1_Bar[[#This Row],[Loose3]]+(CB1_Bar[[#This Row],[Cartons3]]*CB1_Bar[[#This Row],[Carton Size]])+(CB1_Bar[[#This Row],[Cartons2]]*CB1_Bar[[#This Row],[Carton Size]])+(CB1_Bar[[#This Row],[Cartons]]*CB1_Bar[[#This Row],[Carton Size]])) -> 0
A4: 64212 | B4: BEER AUS PACK | C4: BEER | D4: CARLTON ZERO STUBBIE 330ML CTNx24EA | E4: 24 | F4: =SUM(CB1_Bar[[#This Row],[Loose]]+CB1_Bar[[#This Row],[Loose2]]+CB1_Bar[[#This Row],[Loose3]]+(CB1_Bar[[#This Row],[Cartons3]]*CB1_Bar[[#This Row],[Carton Size]])+(CB1_Bar[[#This Row],[Cartons2]]*CB1_Bar[[#This Row],[Carton Size]])+(CB1_Bar[[#This Row],[Cartons]]*CB1_Bar[[#This Row],[Carton Size]])) -> 0
A5: 54419 | B5: BEER AUS PACK | C5: BEER | D5: GREAT NORTHERN SUPER CRISP LAGER 330ML CTNx24EA | E5: 24 | F5: =SUM(CB1_Bar[[#This Row],[Loose]]+CB1_Bar[[#This Row],[Loose2]]+CB1_Bar[[#This Row],[Loose3]]+(CB1_Bar[[#This Row],[Cartons3]]*CB1_Bar[[#This Row],[Carton Size]])+(CB1_Bar[[#This Row],[Cartons2]]*CB1_Bar[[#This Row],[Carton Size]])+(CB1_Bar[[#This Row],[Cartons]]*CB1_Bar[[#This Row],[Carton Size]])) -> 0
A6: 60039 | B6: BEER AUS PACK | C6: BEER | D6: HAHN ULTRA CRISP GLUTEN FREE 4.2% 330ML CTNx24EA | E6: 24 | F6: =SUM(CB1_Bar[[#This Row],[Loose]]+CB1_Bar[[#This Row],[Loose2]]+CB1_Bar[[#This Row],[Loose3]]+(CB1_Bar[[#This Row],[Cartons3]]*CB1_Bar[[#This Row],[Carton Size]])+(CB1_Bar[[#This Row],[Cartons2]]*CB1_Bar[[#This Row],[Carton Size]])+(CB1_Bar[[#This Row],[Cartons]]*CB1_Bar[[#This Row],[Carton Size]])) -> 0
A7: 69689 | B7: BEER AUS PACK | C7: BEER | D7: SWAN DRAUGHT 375ML CAN CTN X24 | E7: 24 | F7: =SUM(CB1_Bar[[#This Row],[Loose]]+CB1_Bar[[#This Row],[Loose2]]+CB1_Bar[[#This Row],[Loose3]]+(CB1_Bar[[#This Row],[Cartons3]]*CB1_Bar[[#This Row],[Carton Size]])+(CB1_Bar[[#This Row],[Cartons2]]*CB1_Bar[[#This Row],[Carton Size]])+(CB1_Bar[[#This Row],[Cartons]]*CB1_Bar[[#This Row],[Carton Size]])) -> 0
A8: 60612 | B8: BEER IMP PACK | C8: BEER | D8: HEINEKEN ZERO 0.0% STUBBIE 330ML CTNx24EA | E8: 24 | F8: =SUM(CB1_Bar[[#This Row],[Loose]]+CB1_Bar[[#This Row],[Loose2]]+CB1_Bar[[#This Row],[Loose3]]+(CB1_Bar[[#This Row],[Cartons3]]*CB1_Bar[[#This Row],[Carton Size]])+(CB1_Bar[[#This Row],[Cartons2]]*CB1_Bar[[#This Row],[Carton Size]])+(CB1_Bar[[#This Row],[Cartons]]*CB1_Bar[[#This Row],[Carton Size]])) -> 0
A9: 383 | B9: BEER PACK | C9: BEER | D9: CORONA BEER 355ML CTNx24EA | E9: 24 | F9: =SUM(CB1_Bar[[#This Row],[Loose]]+CB1_Bar[[#This Row],[Loose2]]+CB1_Bar[[#This Row],[Loose3]]+(CB1_Bar[[#This Row],[Cartons3]]*CB1_Bar[[#This Row],[Carton Size]])+(CB1_Bar[[#This Row],[Cartons2]]*CB1_Bar[[#This Row],[Carton Size]])+(CB1_Bar[[#This Row],[Cartons]]*CB1_Bar[[#This Row],[Carton Size]])) -> 0
A10: 191 | B10: BEER PACK | C10: BEER | D10: CROWN LAGER STUBBIE 24X375ML | E10: 24 | F10: =SUM(CB1_Bar[[#This Row],[Loose]]+CB1_Bar[[#This Row],[Loose2]]+CB1_Bar[[#This Row],[Loose3]]+(CB1_Bar[[#This Row],[Cartons3]]*CB1_Bar[[#This Row],[Carton Size]])+(CB1_Bar[[#This Row],[Cartons2]]*CB1_Bar[[#This Row],[Carton Size]])+(CB1_Bar[[#This Row],[Cartons]]*CB1_Bar[[#This Row],[Carton Size]])) -> 0
A11: 116393 | B11: BEER PACK | C11: BEER | D11: HAHN LIGHT PREMIUM STUBBIE 375ML 3547 CTNx24EA | E11: 24 | F11: =SUM(CB1_Bar[[#This Row],[Loose]]+CB1_Bar[[#This Row],[Loose2]]+CB1_Bar[[#This Row],[Loose3]]+(CB1_Bar[[#This Row],[Cartons3]]*CB1_Bar[[#This Row],[Carton Size]])+(CB1_Bar[[#This Row],[Cartons2]]*CB1_Bar[[#This Row],[Carton Size]])+(CB1_Bar[[#This Row],[Cartons]]*CB1_Bar[[#This Row],[Carton Size]])) -> 0
A12: 36728 | B12: BEER PACK | C12: BEER | D12: HAHN SUPER DRY 3.5pcnt 330ML CTNx24EA 3424 | E12: 24 | F12: =SUM(CB1_Bar[[#This Row],[Loose]]+CB1_Bar[[#This Row],[Loose2]]+CB1_Bar[[#This Row],[Loose3]]+(CB1_Bar[[#This Row],[Cartons3]]*CB1_Bar[[#This Row],[Carton Size]])+(CB1_Bar[[#This Row],[Cartons2]]*CB1_Bar[[#This Row],[Carton Size]])+(CB1_Bar[[#This Row],[Cartons]]*CB1_Bar[[#This Row],[Carton Size]])) -> 0
A13: 22465 | B13: BEER PACK | C13: BEER | D13: HEINEKEN LAGER XLN STUBBIE 330ML CTNx24ea - 3096 | E13: 24 | F13: =SUM(CB1_Bar[[#This Row],[Loose]]+CB1_Bar[[#This Row],[Loose2]]+CB1_Bar[[#This Row],[Loose3]]+(CB1_Bar[[#This Row],[Cartons3]]*CB1_Bar[[#This Row],[Carton Size]])+(CB1_Bar[[#This Row],[Cartons2]]*CB1_Bar[[#This Row],[Carton Size]])+(CB1_Bar[[#This Row],[Cartons]]*CB1_Bar[[#This Row],[Carton Size]])) -> 0
... A193: 47464 | B193: WINE WHITE OTH | C193: WHITE WINE | D193: BABICH BLACK LABEL PINOT GRIS 750ML CTNx12EA | E193: 12 | F193: =SUM(CB1_Bar[[#This Row],[Loose]]+CB1_Bar[[#This Row],[Loose2]]+CB1_Bar[[#This Row],[Loose3]]+(CB1_Bar[[#This Row],[Cartons3]]*CB1_Bar[[#This Row],[Carton Size]])+(CB1_Bar[[#This Row],[Cartons2]]*CB1_Bar[[#This Row],[Carton Size]])+(CB1_Bar[[#This Row],[Cartons]]*CB1_Bar[[#This Row],[Carton Size]])) -> 0

Sheet CB2 Bar
A1: Barcode | B1: Sub Category | C1: Category | D1: Product Name | E1: Carton Size | F1: Total | G1: Cartons | H1: Cartons2 | I1: Cartons3 | J1: Loose | K1: Loose2 | L1: Loose3
A2: 66549 | B2: BEER AUS PACK | C2: BEER | D2: BROOKVALE GINGER BEER 330ML STUBBIE CTNx24EA | E2: 24 | F2: =SUM(CB2_Bar[[#This Row],[Loose]]+CB2_Bar[[#This Row],[Loose2]]+CB2_Bar[[#This Row],[Loose3]]+(CB2_Bar[[#This Row],[Cartons3]]*CB2_Bar[[#This Row],[Carton Size]])+(CB2_Bar[[#This Row],[Cartons2]]*CB2_Bar[[#This Row],[Carton Size]])+(CB2_Bar[[#This Row],[Cartons]]*CB2_Bar[[#This Row],[Carton Size]])) -> 0
A3: 59237 | B3: BEER AUS PACK | C3: BEER | D3: CARLTON DRY STUBBIE 330ML CTNX24EA | E3: 24 | F3: =SUM(CB2_Bar[[#This Row],[Loose]]+CB2_Bar[[#This Row],[Loose2]]+CB2_Bar[[#This Row],[Loose3]]+(CB2_Bar[[#This Row],[Cartons3]]*CB2_Bar[[#This Row],[Carton Size]])+(CB2_Bar[[#This Row],[Cartons2]]*CB2_Bar[[#This Row],[Carton Size]])+(CB2_Bar[[#This Row],[Cartons]]*CB2_Bar[[#This Row],[Carton Size]])) -> 0
A4: 64212 | B4: BEER AUS PACK | C4: BEER | D4: CARLTON ZERO STUBBIE 330ML CTNx24EA | E4: 24 | F4: =SUM(CB2_Bar[[#This Row],[Loose]]+CB2_Bar[[#This Row],[Loose2]]+CB2_Bar[[#This Row],[Loose3]]+(CB2_Bar[[#This Row],[Cartons3]]*CB2_Bar[[#This Row],[Carton Size]])+(CB2_Bar[[#This Row],[Cartons2]]*CB2_Bar[[#This Row],[Carton Size]])+(CB2_Bar[[#This Row],[Cartons]]*CB2_Bar[[#This Row],[Carton Size]])) -> 0
